Not Found: /favicon.ico/
Invalid HTTP_HOST header: '127.0.0.1:8000'. You may need to add '127.0.0.1' to ALLOWED_HOSTS.
Bad Request: /
Invalid HTTP_HOST header: '127.0.0.1:8000'. You may need to add '127.0.0.1' to ALLOWED_HOSTS.
Bad Request: /
Invalid HTTP_HOST header: '127.0.0.1:8000'. You may need to add '127.0.0.1' to ALLOWED_HOSTS.
Bad Request: /
Invalid HTTP_HOST header: '127.0.0.1:8000'. You may need to add '127.0.0.1' to ALLOWED_HOSTS.
Bad Request: /
Invalid HTTP_HOST header: '127.0.0.1:8000'. You may need to add '127.0.0.1' to ALLOWED_HOSTS.
Bad Request: /
Invalid HTTP_HOST header: '127.0.0.1:8000'. You may need to add '127.0.0.1' to ALLOWED_HOSTS.
Bad Request: /
Invalid HTTP_HOST header: '127.0.0.1:8000'. You may need to add '127.0.0.1' to ALLOWED_HOSTS.
Bad Request: /
Invalid HTTP_HOST header: '127.0.0.1:8000'. You may need to add '127.0.0.1' to ALLOWED_HOSTS.
Bad Request: /
Not Found: /favicon.ico/
Not Found: /static/images/favicon.png
Internal Server Error: /anything-but-admin/books/book/
Traceback (most recent call last):
  File "/usr/local/lib/python3.10/site-packages/django/db/backends/utils.py", line 89, in _execute
    return self.cursor.execute(sql, params)
psycopg2.errors.UndefinedColumn: column books_book.cover does not exist
LINE 1: ... "books_book"."is_visible", "books_book"."pages", "books_boo...
                                                             ^


The above exception was the direct cause of the following exception:

Traceback (most recent call last):
  File "/usr/local/lib/python3.10/site-packages/django/core/handlers/exception.py", line 55, in inner
    response = get_response(request)
  File "/usr/local/lib/python3.10/site-packages/django/core/handlers/base.py", line 197, in _get_response
    response = wrapped_callback(request, *callback_args, **callback_kwargs)
  File "/usr/local/lib/python3.10/site-packages/django/contrib/admin/options.py", line 683, in wrapper
    return self.admin_site.admin_view(view)(*args, **kwargs)
  File "/usr/local/lib/python3.10/site-packages/django/utils/decorators.py", line 133, in _wrapped_view
    response = view_func(request, *args, **kwargs)
  File "/usr/local/lib/python3.10/site-packages/django/views/decorators/cache.py", line 62, in _wrapped_view_func
    response = view_func(request, *args, **kwargs)
  File "/usr/local/lib/python3.10/site-packages/django/contrib/admin/sites.py", line 242, in inner
    return view(request, *args, **kwargs)
  File "/usr/local/lib/python3.10/site-packages/django/utils/decorators.py", line 46, in _wrapper
    return bound_method(*args, **kwargs)
  File "/usr/local/lib/python3.10/site-packages/django/utils/decorators.py", line 133, in _wrapped_view
    response = view_func(request, *args, **kwargs)
  File "/usr/local/lib/python3.10/site-packages/django/contrib/admin/options.py", line 1959, in changelist_view
    response = self.response_action(
  File "/usr/local/lib/python3.10/site-packages/django/contrib/admin/options.py", line 1588, in response_action
    response = func(self, request, queryset)
  File "/usr/local/lib/python3.10/site-packages/django/contrib/admin/actions.py", line 39, in delete_selected
    ) = modeladmin.get_deleted_objects(queryset, request)
  File "/usr/local/lib/python3.10/site-packages/django/contrib/admin/options.py", line 2099, in get_deleted_objects
    return get_deleted_objects(objs, request, self.admin_site)
  File "/usr/local/lib/python3.10/site-packages/django/contrib/admin/utils.py", line 114, in get_deleted_objects
    obj = objs[0]
  File "/usr/local/lib/python3.10/site-packages/django/db/models/query.py", line 361, in __getitem__
    qs._fetch_all()
  File "/usr/local/lib/python3.10/site-packages/django/db/models/query.py", line 1507, in _fetch_all
    self._result_cache = list(self._iterable_class(self))
  File "/usr/local/lib/python3.10/site-packages/django/db/models/query.py", line 57, in __iter__
    results = compiler.execute_sql(
  File "/usr/local/lib/python3.10/site-packages/django/db/models/sql/compiler.py", line 1361, in execute_sql
    cursor.execute(sql, params)
  File "/usr/local/lib/python3.10/site-packages/debug_toolbar/panels/sql/tracking.py", line 205, in execute
    return self._record(self.cursor.execute, sql, params)
  File "/usr/local/lib/python3.10/site-packages/debug_toolbar/panels/sql/tracking.py", line 140, in _record
    return method(sql, params)
  File "/usr/local/lib/python3.10/site-packages/django/db/backends/utils.py", line 103, in execute
    return super().execute(sql, params)
  File "/usr/local/lib/python3.10/site-packages/django/db/backends/utils.py", line 67, in execute
    return self._execute_with_wrappers(
  File "/usr/local/lib/python3.10/site-packages/django/db/backends/utils.py", line 80, in _execute_with_wrappers
    return executor(sql, params, many, context)
  File "/usr/local/lib/python3.10/site-packages/django/db/backends/utils.py", line 84, in _execute
    with self.db.wrap_database_errors:
  File "/usr/local/lib/python3.10/site-packages/django/db/utils.py", line 91, in __exit__
    raise dj_exc_value.with_traceback(traceback) from exc_value
  File "/usr/local/lib/python3.10/site-packages/django/db/backends/utils.py", line 89, in _execute
    return self.cursor.execute(sql, params)
django.db.utils.ProgrammingError: column books_book.cover does not exist
LINE 1: ... "books_book"."is_visible", "books_book"."pages", "books_boo...
                                                             ^

Internal Server Error: /anything-but-admin/books/book/
Traceback (most recent call last):
  File "/usr/local/lib/python3.10/site-packages/django/db/backends/utils.py", line 89, in _execute
    return self.cursor.execute(sql, params)
psycopg2.errors.UndefinedColumn: column books_book.cover does not exist
LINE 1: ... "books_book"."is_visible", "books_book"."pages", "books_boo...
                                                             ^


The above exception was the direct cause of the following exception:

Traceback (most recent call last):
  File "/usr/local/lib/python3.10/site-packages/django/core/handlers/exception.py", line 55, in inner
    response = get_response(request)
  File "/usr/local/lib/python3.10/site-packages/django/core/handlers/base.py", line 197, in _get_response
    response = wrapped_callback(request, *callback_args, **callback_kwargs)
  File "/usr/local/lib/python3.10/site-packages/django/contrib/admin/options.py", line 683, in wrapper
    return self.admin_site.admin_view(view)(*args, **kwargs)
  File "/usr/local/lib/python3.10/site-packages/django/utils/decorators.py", line 133, in _wrapped_view
    response = view_func(request, *args, **kwargs)
  File "/usr/local/lib/python3.10/site-packages/django/views/decorators/cache.py", line 62, in _wrapped_view_func
    response = view_func(request, *args, **kwargs)
  File "/usr/local/lib/python3.10/site-packages/django/contrib/admin/sites.py", line 242, in inner
    return view(request, *args, **kwargs)
  File "/usr/local/lib/python3.10/site-packages/django/utils/decorators.py", line 46, in _wrapper
    return bound_method(*args, **kwargs)
  File "/usr/local/lib/python3.10/site-packages/django/utils/decorators.py", line 133, in _wrapped_view
    response = view_func(request, *args, **kwargs)
  File "/usr/local/lib/python3.10/site-packages/django/contrib/admin/options.py", line 2063, in changelist_view
    "selection_note": _("0 of %(cnt)s selected") % {"cnt": len(cl.result_list)},
  File "/usr/local/lib/python3.10/site-packages/django/db/models/query.py", line 302, in __len__
    self._fetch_all()
  File "/usr/local/lib/python3.10/site-packages/django/db/models/query.py", line 1507, in _fetch_all
    self._result_cache = list(self._iterable_class(self))
  File "/usr/local/lib/python3.10/site-packages/django/db/models/query.py", line 57, in __iter__
    results = compiler.execute_sql(
  File "/usr/local/lib/python3.10/site-packages/django/db/models/sql/compiler.py", line 1361, in execute_sql
    cursor.execute(sql, params)
  File "/usr/local/lib/python3.10/site-packages/debug_toolbar/panels/sql/tracking.py", line 205, in execute
    return self._record(self.cursor.execute, sql, params)
  File "/usr/local/lib/python3.10/site-packages/debug_toolbar/panels/sql/tracking.py", line 140, in _record
    return method(sql, params)
  File "/usr/local/lib/python3.10/site-packages/django/db/backends/utils.py", line 103, in execute
    return super().execute(sql, params)
  File "/usr/local/lib/python3.10/site-packages/django/db/backends/utils.py", line 67, in execute
    return self._execute_with_wrappers(
  File "/usr/local/lib/python3.10/site-packages/django/db/backends/utils.py", line 80, in _execute_with_wrappers
    return executor(sql, params, many, context)
  File "/usr/local/lib/python3.10/site-packages/django/db/backends/utils.py", line 84, in _execute
    with self.db.wrap_database_errors:
  File "/usr/local/lib/python3.10/site-packages/django/db/utils.py", line 91, in __exit__
    raise dj_exc_value.with_traceback(traceback) from exc_value
  File "/usr/local/lib/python3.10/site-packages/django/db/backends/utils.py", line 89, in _execute
    return self.cursor.execute(sql, params)
django.db.utils.ProgrammingError: column books_book.cover does not exist
LINE 1: ... "books_book"."is_visible", "books_book"."pages", "books_boo...
                                                             ^

Internal Server Error: /profile/
Traceback (most recent call last):
  File "/usr/local/lib/python3.10/site-packages/django/db/backends/utils.py", line 89, in _execute
    return self.cursor.execute(sql, params)
psycopg2.errors.UndefinedColumn: column books_book.cover does not exist
LINE 1: ... "books_book"."is_visible", "books_book"."pages", "books_boo...
                                                             ^


The above exception was the direct cause of the following exception:

Traceback (most recent call last):
  File "/usr/local/lib/python3.10/site-packages/django/core/handlers/exception.py", line 55, in inner
    response = get_response(request)
  File "/usr/local/lib/python3.10/site-packages/django/core/handlers/base.py", line 220, in _get_response
    response = response.render()
  File "/usr/local/lib/python3.10/site-packages/django/template/response.py", line 114, in render
    self.content = self.rendered_content
  File "/usr/local/lib/python3.10/site-packages/django/template/response.py", line 92, in rendered_content
    return template.render(context, self._request)
  File "/usr/local/lib/python3.10/site-packages/django/template/backends/django.py", line 62, in render
    return self.template.render(context)
  File "/usr/local/lib/python3.10/site-packages/django/template/base.py", line 175, in render
    return self._render(context)
  File "/usr/local/lib/python3.10/site-packages/django/test/utils.py", line 111, in instrumented_test_render
    return self.nodelist.render(context)
  File "/usr/local/lib/python3.10/site-packages/django/template/base.py", line 1000, in render
    return SafeString("".join([node.render_annotated(context) for node in self]))
  File "/usr/local/lib/python3.10/site-packages/django/template/base.py", line 1000, in <listcomp>
    return SafeString("".join([node.render_annotated(context) for node in self]))
  File "/usr/local/lib/python3.10/site-packages/django/template/base.py", line 958, in render_annotated
    return self.render(context)
  File "/usr/local/lib/python3.10/site-packages/django/template/loader_tags.py", line 157, in render
    return compiled_parent._render(context)
  File "/usr/local/lib/python3.10/site-packages/django/test/utils.py", line 111, in instrumented_test_render
    return self.nodelist.render(context)
  File "/usr/local/lib/python3.10/site-packages/django/template/base.py", line 1000, in render
    return SafeString("".join([node.render_annotated(context) for node in self]))
  File "/usr/local/lib/python3.10/site-packages/django/template/base.py", line 1000, in <listcomp>
    return SafeString("".join([node.render_annotated(context) for node in self]))
  File "/usr/local/lib/python3.10/site-packages/django/template/base.py", line 958, in render_annotated
    return self.render(context)
  File "/usr/local/lib/python3.10/site-packages/django/template/loader_tags.py", line 63, in render
    result = block.nodelist.render(context)
  File "/usr/local/lib/python3.10/site-packages/django/template/base.py", line 1000, in render
    return SafeString("".join([node.render_annotated(context) for node in self]))
  File "/usr/local/lib/python3.10/site-packages/django/template/base.py", line 1000, in <listcomp>
    return SafeString("".join([node.render_annotated(context) for node in self]))
  File "/usr/local/lib/python3.10/site-packages/django/template/base.py", line 958, in render_annotated
    return self.render(context)
  File "/usr/local/lib/python3.10/site-packages/django/template/defaulttags.py", line 322, in render
    return nodelist.render(context)
  File "/usr/local/lib/python3.10/site-packages/django/template/base.py", line 1000, in render
    return SafeString("".join([node.render_annotated(context) for node in self]))
  File "/usr/local/lib/python3.10/site-packages/django/template/base.py", line 1000, in <listcomp>
    return SafeString("".join([node.render_annotated(context) for node in self]))
  File "/usr/local/lib/python3.10/site-packages/django/template/base.py", line 958, in render_annotated
    return self.render(context)
  File "/usr/local/lib/python3.10/site-packages/django/template/loader_tags.py", line 208, in render
    return template.render(context)
  File "/usr/local/lib/python3.10/site-packages/django/template/base.py", line 177, in render
    return self._render(context)
  File "/usr/local/lib/python3.10/site-packages/django/test/utils.py", line 111, in instrumented_test_render
    return self.nodelist.render(context)
  File "/usr/local/lib/python3.10/site-packages/django/template/base.py", line 1000, in render
    return SafeString("".join([node.render_annotated(context) for node in self]))
  File "/usr/local/lib/python3.10/site-packages/django/template/base.py", line 1000, in <listcomp>
    return SafeString("".join([node.render_annotated(context) for node in self]))
  File "/usr/local/lib/python3.10/site-packages/django/template/base.py", line 958, in render_annotated
    return self.render(context)
  File "/usr/local/lib/python3.10/site-packages/django/template/defaulttags.py", line 194, in render
    len_values = len(values)
  File "/usr/local/lib/python3.10/site-packages/django/db/models/query.py", line 302, in __len__
    self._fetch_all()
  File "/usr/local/lib/python3.10/site-packages/django/db/models/query.py", line 1507, in _fetch_all
    self._result_cache = list(self._iterable_class(self))
  File "/usr/local/lib/python3.10/site-packages/django/db/models/query.py", line 57, in __iter__
    results = compiler.execute_sql(
  File "/usr/local/lib/python3.10/site-packages/django/db/models/sql/compiler.py", line 1361, in execute_sql
    cursor.execute(sql, params)
  File "/usr/local/lib/python3.10/site-packages/debug_toolbar/panels/sql/tracking.py", line 205, in execute
    return self._record(self.cursor.execute, sql, params)
  File "/usr/local/lib/python3.10/site-packages/debug_toolbar/panels/sql/tracking.py", line 140, in _record
    return method(sql, params)
  File "/usr/local/lib/python3.10/site-packages/django/db/backends/utils.py", line 103, in execute
    return super().execute(sql, params)
  File "/usr/local/lib/python3.10/site-packages/django/db/backends/utils.py", line 67, in execute
    return self._execute_with_wrappers(
  File "/usr/local/lib/python3.10/site-packages/django/db/backends/utils.py", line 80, in _execute_with_wrappers
    return executor(sql, params, many, context)
  File "/usr/local/lib/python3.10/site-packages/django/db/backends/utils.py", line 84, in _execute
    with self.db.wrap_database_errors:
  File "/usr/local/lib/python3.10/site-packages/django/db/utils.py", line 91, in __exit__
    raise dj_exc_value.with_traceback(traceback) from exc_value
  File "/usr/local/lib/python3.10/site-packages/django/db/backends/utils.py", line 89, in _execute
    return self.cursor.execute(sql, params)
django.db.utils.ProgrammingError: column books_book.cover does not exist
LINE 1: ... "books_book"."is_visible", "books_book"."pages", "books_boo...
                                                             ^

Internal Server Error: /
Traceback (most recent call last):
  File "/usr/local/lib/python3.10/site-packages/django/db/backends/utils.py", line 89, in _execute
    return self.cursor.execute(sql, params)
psycopg2.errors.UndefinedTable: relation "books_book" does not exist
LINE 1: SELECT COUNT(*) AS "__count" FROM "books_book" WHERE "books_...
                                          ^


The above exception was the direct cause of the following exception:

Traceback (most recent call last):
  File "/usr/local/lib/python3.10/site-packages/django/core/handlers/exception.py", line 55, in inner
    response = get_response(request)
  File "/usr/local/lib/python3.10/site-packages/django/core/handlers/base.py", line 197, in _get_response
    response = wrapped_callback(request, *callback_args, **callback_kwargs)
  File "/usr/local/lib/python3.10/site-packages/django/views/generic/base.py", line 84, in view
    return self.dispatch(request, *args, **kwargs)
  File "/usr/local/lib/python3.10/site-packages/django/views/generic/base.py", line 119, in dispatch
    return handler(request, *args, **kwargs)
  File "/usr/local/lib/python3.10/site-packages/django/views/generic/list.py", line 174, in get
    context = self.get_context_data()
  File "/usr/local/lib/python3.10/site-packages/django/views/generic/list.py", line 128, in get_context_data
    paginator, page, queryset, is_paginated = self.paginate_queryset(
  File "/usr/local/lib/python3.10/site-packages/django/views/generic/list.py", line 73, in paginate_queryset
    page = paginator.page(page_number)
  File "/usr/local/lib/python3.10/site-packages/django/core/paginator.py", line 75, in page
    number = self.validate_number(number)
  File "/usr/local/lib/python3.10/site-packages/django/core/paginator.py", line 53, in validate_number
    if number > self.num_pages:
  File "/usr/local/lib/python3.10/site-packages/django/utils/functional.py", line 49, in __get__
    res = instance.__dict__[self.name] = self.func(instance)
  File "/usr/local/lib/python3.10/site-packages/django/core/paginator.py", line 102, in num_pages
    if self.count == 0 and not self.allow_empty_first_page:
  File "/usr/local/lib/python3.10/site-packages/django/utils/functional.py", line 49, in __get__
    res = instance.__dict__[self.name] = self.func(instance)
  File "/usr/local/lib/python3.10/site-packages/django/core/paginator.py", line 96, in count
    return c()
  File "/usr/local/lib/python3.10/site-packages/django/db/models/query.py", line 470, in count
    return self.query.get_count(using=self.db)
  File "/usr/local/lib/python3.10/site-packages/django/db/models/sql/query.py", line 552, in get_count
    number = obj.get_aggregation(using, ["__count"])["__count"]
  File "/usr/local/lib/python3.10/site-packages/django/db/models/sql/query.py", line 537, in get_aggregation
    result = compiler.execute_sql(SINGLE)
  File "/usr/local/lib/python3.10/site-packages/django/db/models/sql/compiler.py", line 1361, in execute_sql
    cursor.execute(sql, params)
  File "/usr/local/lib/python3.10/site-packages/debug_toolbar/panels/sql/tracking.py", line 205, in execute
    return self._record(self.cursor.execute, sql, params)
  File "/usr/local/lib/python3.10/site-packages/debug_toolbar/panels/sql/tracking.py", line 140, in _record
    return method(sql, params)
  File "/usr/local/lib/python3.10/site-packages/django/db/backends/utils.py", line 103, in execute
    return super().execute(sql, params)
  File "/usr/local/lib/python3.10/site-packages/django/db/backends/utils.py", line 67, in execute
    return self._execute_with_wrappers(
  File "/usr/local/lib/python3.10/site-packages/django/db/backends/utils.py", line 80, in _execute_with_wrappers
    return executor(sql, params, many, context)
  File "/usr/local/lib/python3.10/site-packages/django/db/backends/utils.py", line 84, in _execute
    with self.db.wrap_database_errors:
  File "/usr/local/lib/python3.10/site-packages/django/db/utils.py", line 91, in __exit__
    raise dj_exc_value.with_traceback(traceback) from exc_value
  File "/usr/local/lib/python3.10/site-packages/django/db/backends/utils.py", line 89, in _execute
    return self.cursor.execute(sql, params)
django.db.utils.ProgrammingError: relation "books_book" does not exist
LINE 1: SELECT COUNT(*) AS "__count" FROM "books_book" WHERE "books_...
                                          ^

Internal Server Error: /
Traceback (most recent call last):
  File "/usr/local/lib/python3.10/site-packages/django/contrib/sessions/backends/base.py", line 187, in _get_session
    return self._session_cache
AttributeError: 'SessionStore' object has no attribute '_session_cache'

During handling of the above exception, another exception occurred:

Traceback (most recent call last):
  File "/usr/local/lib/python3.10/site-packages/django/db/backends/utils.py", line 89, in _execute
    return self.cursor.execute(sql, params)
psycopg2.errors.UndefinedTable: relation "django_session" does not exist
LINE 1: ...ession_data", "django_session"."expire_date" FROM "django_se...
                                                             ^


The above exception was the direct cause of the following exception:

Traceback (most recent call last):
  File "/usr/local/lib/python3.10/site-packages/django/core/handlers/exception.py", line 55, in inner
    response = get_response(request)
  File "/usr/local/lib/python3.10/site-packages/debug_toolbar/middleware.py", line 67, in __call__
    panel.generate_stats(request, response)
  File "/usr/local/lib/python3.10/site-packages/debug_toolbar/panels/request.py", line 66, in generate_stats
    for k in sorted(request.session.keys())
  File "/usr/local/lib/python3.10/site-packages/django/contrib/sessions/backends/base.py", line 123, in keys
    return self._session.keys()
  File "/usr/local/lib/python3.10/site-packages/django/contrib/sessions/backends/base.py", line 192, in _get_session
    self._session_cache = self.load()
  File "/usr/local/lib/python3.10/site-packages/django/contrib/sessions/backends/db.py", line 42, in load
    s = self._get_session_from_db()
  File "/usr/local/lib/python3.10/site-packages/django/contrib/sessions/backends/db.py", line 32, in _get_session_from_db
    return self.model.objects.get(
  File "/usr/local/lib/python3.10/site-packages/django/db/models/manager.py", line 85, in manager_method
    return getattr(self.get_queryset(), name)(*args, **kwargs)
  File "/usr/local/lib/python3.10/site-packages/django/db/models/query.py", line 492, in get
    num = len(clone)
  File "/usr/local/lib/python3.10/site-packages/django/db/models/query.py", line 302, in __len__
    self._fetch_all()
  File "/usr/local/lib/python3.10/site-packages/django/db/models/query.py", line 1507, in _fetch_all
    self._result_cache = list(self._iterable_class(self))
  File "/usr/local/lib/python3.10/site-packages/django/db/models/query.py", line 57, in __iter__
    results = compiler.execute_sql(
  File "/usr/local/lib/python3.10/site-packages/django/db/models/sql/compiler.py", line 1361, in execute_sql
    cursor.execute(sql, params)
  File "/usr/local/lib/python3.10/site-packages/django/db/backends/utils.py", line 103, in execute
    return super().execute(sql, params)
  File "/usr/local/lib/python3.10/site-packages/django/db/backends/utils.py", line 67, in execute
    return self._execute_with_wrappers(
  File "/usr/local/lib/python3.10/site-packages/django/db/backends/utils.py", line 80, in _execute_with_wrappers
    return executor(sql, params, many, context)
  File "/usr/local/lib/python3.10/site-packages/django/db/backends/utils.py", line 84, in _execute
    with self.db.wrap_database_errors:
  File "/usr/local/lib/python3.10/site-packages/django/db/utils.py", line 91, in __exit__
    raise dj_exc_value.with_traceback(traceback) from exc_value
  File "/usr/local/lib/python3.10/site-packages/django/db/backends/utils.py", line 89, in _execute
    return self.cursor.execute(sql, params)
django.db.utils.ProgrammingError: relation "django_session" does not exist
LINE 1: ...ession_data", "django_session"."expire_date" FROM "django_se...
                                                             ^

Internal Server Error: /favicon.ico/
Traceback (most recent call last):
  File "/usr/local/lib/python3.10/site-packages/django/db/backends/utils.py", line 89, in _execute
    return self.cursor.execute(sql, params)
psycopg2.errors.UndefinedTable: relation "accounts_customuser" does not exist
LINE 1: ...omuser"."bio", "accounts_customuser"."email" FROM "accounts_...
                                                             ^


The above exception was the direct cause of the following exception:

Traceback (most recent call last):
  File "/usr/local/lib/python3.10/site-packages/django/core/handlers/exception.py", line 55, in inner
    response = get_response(request)
  File "/usr/local/lib/python3.10/site-packages/django/core/handlers/base.py", line 197, in _get_response
    response = wrapped_callback(request, *callback_args, **callback_kwargs)
  File "/usr/local/lib/python3.10/site-packages/django/views/generic/base.py", line 84, in view
    return self.dispatch(request, *args, **kwargs)
  File "/usr/local/lib/python3.10/site-packages/django/views/generic/base.py", line 119, in dispatch
    return handler(request, *args, **kwargs)
  File "/usr/local/lib/python3.10/site-packages/django/views/generic/list.py", line 154, in get
    self.object_list = self.get_queryset()
  File "/code/books/views.py", line 134, in get_queryset
    user = get_object_or_404(
  File "/usr/local/lib/python3.10/site-packages/django/shortcuts.py", line 85, in get_object_or_404
    return queryset.get(*args, **kwargs)
  File "/usr/local/lib/python3.10/site-packages/django/db/models/query.py", line 492, in get
    num = len(clone)
  File "/usr/local/lib/python3.10/site-packages/django/db/models/query.py", line 302, in __len__
    self._fetch_all()
  File "/usr/local/lib/python3.10/site-packages/django/db/models/query.py", line 1507, in _fetch_all
    self._result_cache = list(self._iterable_class(self))
  File "/usr/local/lib/python3.10/site-packages/django/db/models/query.py", line 57, in __iter__
    results = compiler.execute_sql(
  File "/usr/local/lib/python3.10/site-packages/django/db/models/sql/compiler.py", line 1361, in execute_sql
    cursor.execute(sql, params)
  File "/usr/local/lib/python3.10/site-packages/debug_toolbar/panels/sql/tracking.py", line 205, in execute
    return self._record(self.cursor.execute, sql, params)
  File "/usr/local/lib/python3.10/site-packages/debug_toolbar/panels/sql/tracking.py", line 140, in _record
    return method(sql, params)
  File "/usr/local/lib/python3.10/site-packages/django/db/backends/utils.py", line 103, in execute
    return super().execute(sql, params)
  File "/usr/local/lib/python3.10/site-packages/django/db/backends/utils.py", line 67, in execute
    return self._execute_with_wrappers(
  File "/usr/local/lib/python3.10/site-packages/django/db/backends/utils.py", line 80, in _execute_with_wrappers
    return executor(sql, params, many, context)
  File "/usr/local/lib/python3.10/site-packages/django/db/backends/utils.py", line 84, in _execute
    with self.db.wrap_database_errors:
  File "/usr/local/lib/python3.10/site-packages/django/db/utils.py", line 91, in __exit__
    raise dj_exc_value.with_traceback(traceback) from exc_value
  File "/usr/local/lib/python3.10/site-packages/django/db/backends/utils.py", line 89, in _execute
    return self.cursor.execute(sql, params)
django.db.utils.ProgrammingError: relation "accounts_customuser" does not exist
LINE 1: ...omuser"."bio", "accounts_customuser"."email" FROM "accounts_...
                                                             ^

Internal Server Error: /favicon.ico/
Traceback (most recent call last):
  File "/usr/local/lib/python3.10/site-packages/django/contrib/sessions/backends/base.py", line 187, in _get_session
    return self._session_cache
AttributeError: 'SessionStore' object has no attribute '_session_cache'

During handling of the above exception, another exception occurred:

Traceback (most recent call last):
  File "/usr/local/lib/python3.10/site-packages/django/db/backends/utils.py", line 89, in _execute
    return self.cursor.execute(sql, params)
psycopg2.errors.UndefinedTable: relation "django_session" does not exist
LINE 1: ...ession_data", "django_session"."expire_date" FROM "django_se...
                                                             ^


The above exception was the direct cause of the following exception:

Traceback (most recent call last):
  File "/usr/local/lib/python3.10/site-packages/django/core/handlers/exception.py", line 55, in inner
    response = get_response(request)
  File "/usr/local/lib/python3.10/site-packages/debug_toolbar/middleware.py", line 67, in __call__
    panel.generate_stats(request, response)
  File "/usr/local/lib/python3.10/site-packages/debug_toolbar/panels/request.py", line 66, in generate_stats
    for k in sorted(request.session.keys())
  File "/usr/local/lib/python3.10/site-packages/django/contrib/sessions/backends/base.py", line 123, in keys
    return self._session.keys()
  File "/usr/local/lib/python3.10/site-packages/django/contrib/sessions/backends/base.py", line 192, in _get_session
    self._session_cache = self.load()
  File "/usr/local/lib/python3.10/site-packages/django/contrib/sessions/backends/db.py", line 42, in load
    s = self._get_session_from_db()
  File "/usr/local/lib/python3.10/site-packages/django/contrib/sessions/backends/db.py", line 32, in _get_session_from_db
    return self.model.objects.get(
  File "/usr/local/lib/python3.10/site-packages/django/db/models/manager.py", line 85, in manager_method
    return getattr(self.get_queryset(), name)(*args, **kwargs)
  File "/usr/local/lib/python3.10/site-packages/django/db/models/query.py", line 492, in get
    num = len(clone)
  File "/usr/local/lib/python3.10/site-packages/django/db/models/query.py", line 302, in __len__
    self._fetch_all()
  File "/usr/local/lib/python3.10/site-packages/django/db/models/query.py", line 1507, in _fetch_all
    self._result_cache = list(self._iterable_class(self))
  File "/usr/local/lib/python3.10/site-packages/django/db/models/query.py", line 57, in __iter__
    results = compiler.execute_sql(
  File "/usr/local/lib/python3.10/site-packages/django/db/models/sql/compiler.py", line 1361, in execute_sql
    cursor.execute(sql, params)
  File "/usr/local/lib/python3.10/site-packages/django/db/backends/utils.py", line 103, in execute
    return super().execute(sql, params)
  File "/usr/local/lib/python3.10/site-packages/django/db/backends/utils.py", line 67, in execute
    return self._execute_with_wrappers(
  File "/usr/local/lib/python3.10/site-packages/django/db/backends/utils.py", line 80, in _execute_with_wrappers
    return executor(sql, params, many, context)
  File "/usr/local/lib/python3.10/site-packages/django/db/backends/utils.py", line 84, in _execute
    with self.db.wrap_database_errors:
  File "/usr/local/lib/python3.10/site-packages/django/db/utils.py", line 91, in __exit__
    raise dj_exc_value.with_traceback(traceback) from exc_value
  File "/usr/local/lib/python3.10/site-packages/django/db/backends/utils.py", line 89, in _execute
    return self.cursor.execute(sql, params)
django.db.utils.ProgrammingError: relation "django_session" does not exist
LINE 1: ...ession_data", "django_session"."expire_date" FROM "django_se...
                                                             ^

Internal Server Error: /
Traceback (most recent call last):
  File "/usr/local/lib/python3.10/site-packages/django/db/backends/utils.py", line 89, in _execute
    return self.cursor.execute(sql, params)
psycopg2.errors.UndefinedTable: relation "books_book" does not exist
LINE 1: SELECT COUNT(*) AS "__count" FROM "books_book" WHERE "books_...
                                          ^


The above exception was the direct cause of the following exception:

Traceback (most recent call last):
  File "/usr/local/lib/python3.10/site-packages/django/core/handlers/exception.py", line 55, in inner
    response = get_response(request)
  File "/usr/local/lib/python3.10/site-packages/django/core/handlers/base.py", line 197, in _get_response
    response = wrapped_callback(request, *callback_args, **callback_kwargs)
  File "/usr/local/lib/python3.10/site-packages/django/views/generic/base.py", line 84, in view
    return self.dispatch(request, *args, **kwargs)
  File "/usr/local/lib/python3.10/site-packages/django/views/generic/base.py", line 119, in dispatch
    return handler(request, *args, **kwargs)
  File "/usr/local/lib/python3.10/site-packages/django/views/generic/list.py", line 174, in get
    context = self.get_context_data()
  File "/usr/local/lib/python3.10/site-packages/django/views/generic/list.py", line 128, in get_context_data
    paginator, page, queryset, is_paginated = self.paginate_queryset(
  File "/usr/local/lib/python3.10/site-packages/django/views/generic/list.py", line 73, in paginate_queryset
    page = paginator.page(page_number)
  File "/usr/local/lib/python3.10/site-packages/django/core/paginator.py", line 75, in page
    number = self.validate_number(number)
  File "/usr/local/lib/python3.10/site-packages/django/core/paginator.py", line 53, in validate_number
    if number > self.num_pages:
  File "/usr/local/lib/python3.10/site-packages/django/utils/functional.py", line 49, in __get__
    res = instance.__dict__[self.name] = self.func(instance)
  File "/usr/local/lib/python3.10/site-packages/django/core/paginator.py", line 102, in num_pages
    if self.count == 0 and not self.allow_empty_first_page:
  File "/usr/local/lib/python3.10/site-packages/django/utils/functional.py", line 49, in __get__
    res = instance.__dict__[self.name] = self.func(instance)
  File "/usr/local/lib/python3.10/site-packages/django/core/paginator.py", line 96, in count
    return c()
  File "/usr/local/lib/python3.10/site-packages/django/db/models/query.py", line 470, in count
    return self.query.get_count(using=self.db)
  File "/usr/local/lib/python3.10/site-packages/django/db/models/sql/query.py", line 552, in get_count
    number = obj.get_aggregation(using, ["__count"])["__count"]
  File "/usr/local/lib/python3.10/site-packages/django/db/models/sql/query.py", line 537, in get_aggregation
    result = compiler.execute_sql(SINGLE)
  File "/usr/local/lib/python3.10/site-packages/django/db/models/sql/compiler.py", line 1361, in execute_sql
    cursor.execute(sql, params)
  File "/usr/local/lib/python3.10/site-packages/debug_toolbar/panels/sql/tracking.py", line 205, in execute
    return self._record(self.cursor.execute, sql, params)
  File "/usr/local/lib/python3.10/site-packages/debug_toolbar/panels/sql/tracking.py", line 140, in _record
    return method(sql, params)
  File "/usr/local/lib/python3.10/site-packages/django/db/backends/utils.py", line 103, in execute
    return super().execute(sql, params)
  File "/usr/local/lib/python3.10/site-packages/django/db/backends/utils.py", line 67, in execute
    return self._execute_with_wrappers(
  File "/usr/local/lib/python3.10/site-packages/django/db/backends/utils.py", line 80, in _execute_with_wrappers
    return executor(sql, params, many, context)
  File "/usr/local/lib/python3.10/site-packages/django/db/backends/utils.py", line 84, in _execute
    with self.db.wrap_database_errors:
  File "/usr/local/lib/python3.10/site-packages/django/db/utils.py", line 91, in __exit__
    raise dj_exc_value.with_traceback(traceback) from exc_value
  File "/usr/local/lib/python3.10/site-packages/django/db/backends/utils.py", line 89, in _execute
    return self.cursor.execute(sql, params)
django.db.utils.ProgrammingError: relation "books_book" does not exist
LINE 1: SELECT COUNT(*) AS "__count" FROM "books_book" WHERE "books_...
                                          ^

Not Found: /favicon.ico/
Internal Server Error: /
Traceback (most recent call last):
  File "/usr/local/lib/python3.10/site-packages/django/db/backends/utils.py", line 89, in _execute
    return self.cursor.execute(sql, params)
psycopg2.errors.UndefinedTable: relation "books_book" does not exist
LINE 1: SELECT COUNT(*) AS "__count" FROM "books_book" WHERE "books_...
                                          ^


The above exception was the direct cause of the following exception:

Traceback (most recent call last):
  File "/usr/local/lib/python3.10/site-packages/django/core/handlers/exception.py", line 55, in inner
    response = get_response(request)
  File "/usr/local/lib/python3.10/site-packages/django/core/handlers/base.py", line 197, in _get_response
    response = wrapped_callback(request, *callback_args, **callback_kwargs)
  File "/usr/local/lib/python3.10/site-packages/django/views/generic/base.py", line 84, in view
    return self.dispatch(request, *args, **kwargs)
  File "/usr/local/lib/python3.10/site-packages/django/views/generic/base.py", line 119, in dispatch
    return handler(request, *args, **kwargs)
  File "/usr/local/lib/python3.10/site-packages/django/views/generic/list.py", line 174, in get
    context = self.get_context_data()
  File "/usr/local/lib/python3.10/site-packages/django/views/generic/list.py", line 128, in get_context_data
    paginator, page, queryset, is_paginated = self.paginate_queryset(
  File "/usr/local/lib/python3.10/site-packages/django/views/generic/list.py", line 73, in paginate_queryset
    page = paginator.page(page_number)
  File "/usr/local/lib/python3.10/site-packages/django/core/paginator.py", line 75, in page
    number = self.validate_number(number)
  File "/usr/local/lib/python3.10/site-packages/django/core/paginator.py", line 53, in validate_number
    if number > self.num_pages:
  File "/usr/local/lib/python3.10/site-packages/django/utils/functional.py", line 49, in __get__
    res = instance.__dict__[self.name] = self.func(instance)
  File "/usr/local/lib/python3.10/site-packages/django/core/paginator.py", line 102, in num_pages
    if self.count == 0 and not self.allow_empty_first_page:
  File "/usr/local/lib/python3.10/site-packages/django/utils/functional.py", line 49, in __get__
    res = instance.__dict__[self.name] = self.func(instance)
  File "/usr/local/lib/python3.10/site-packages/django/core/paginator.py", line 96, in count
    return c()
  File "/usr/local/lib/python3.10/site-packages/django/db/models/query.py", line 470, in count
    return self.query.get_count(using=self.db)
  File "/usr/local/lib/python3.10/site-packages/django/db/models/sql/query.py", line 552, in get_count
    number = obj.get_aggregation(using, ["__count"])["__count"]
  File "/usr/local/lib/python3.10/site-packages/django/db/models/sql/query.py", line 537, in get_aggregation
    result = compiler.execute_sql(SINGLE)
  File "/usr/local/lib/python3.10/site-packages/django/db/models/sql/compiler.py", line 1361, in execute_sql
    cursor.execute(sql, params)
  File "/usr/local/lib/python3.10/site-packages/debug_toolbar/panels/sql/tracking.py", line 205, in execute
    return self._record(self.cursor.execute, sql, params)
  File "/usr/local/lib/python3.10/site-packages/debug_toolbar/panels/sql/tracking.py", line 140, in _record
    return method(sql, params)
  File "/usr/local/lib/python3.10/site-packages/django/db/backends/utils.py", line 103, in execute
    return super().execute(sql, params)
  File "/usr/local/lib/python3.10/site-packages/django/db/backends/utils.py", line 67, in execute
    return self._execute_with_wrappers(
  File "/usr/local/lib/python3.10/site-packages/django/db/backends/utils.py", line 80, in _execute_with_wrappers
    return executor(sql, params, many, context)
  File "/usr/local/lib/python3.10/site-packages/django/db/backends/utils.py", line 84, in _execute
    with self.db.wrap_database_errors:
  File "/usr/local/lib/python3.10/site-packages/django/db/utils.py", line 91, in __exit__
    raise dj_exc_value.with_traceback(traceback) from exc_value
  File "/usr/local/lib/python3.10/site-packages/django/db/backends/utils.py", line 89, in _execute
    return self.cursor.execute(sql, params)
django.db.utils.ProgrammingError: relation "books_book" does not exist
LINE 1: SELECT COUNT(*) AS "__count" FROM "books_book" WHERE "books_...
                                          ^

Internal Server Error: /
Traceback (most recent call last):
  File "/usr/local/lib/python3.10/site-packages/django/db/backends/utils.py", line 89, in _execute
    return self.cursor.execute(sql, params)
psycopg2.errors.UndefinedTable: relation "books_book" does not exist
LINE 1: SELECT COUNT(*) AS "__count" FROM "books_book" WHERE "books_...
                                          ^


The above exception was the direct cause of the following exception:

Traceback (most recent call last):
  File "/usr/local/lib/python3.10/site-packages/django/core/handlers/exception.py", line 55, in inner
    response = get_response(request)
  File "/usr/local/lib/python3.10/site-packages/django/core/handlers/base.py", line 197, in _get_response
    response = wrapped_callback(request, *callback_args, **callback_kwargs)
  File "/usr/local/lib/python3.10/site-packages/django/views/generic/base.py", line 84, in view
    return self.dispatch(request, *args, **kwargs)
  File "/usr/local/lib/python3.10/site-packages/django/views/generic/base.py", line 119, in dispatch
    return handler(request, *args, **kwargs)
  File "/usr/local/lib/python3.10/site-packages/django/views/generic/list.py", line 174, in get
    context = self.get_context_data()
  File "/usr/local/lib/python3.10/site-packages/django/views/generic/list.py", line 128, in get_context_data
    paginator, page, queryset, is_paginated = self.paginate_queryset(
  File "/usr/local/lib/python3.10/site-packages/django/views/generic/list.py", line 73, in paginate_queryset
    page = paginator.page(page_number)
  File "/usr/local/lib/python3.10/site-packages/django/core/paginator.py", line 75, in page
    number = self.validate_number(number)
  File "/usr/local/lib/python3.10/site-packages/django/core/paginator.py", line 53, in validate_number
    if number > self.num_pages:
  File "/usr/local/lib/python3.10/site-packages/django/utils/functional.py", line 49, in __get__
    res = instance.__dict__[self.name] = self.func(instance)
  File "/usr/local/lib/python3.10/site-packages/django/core/paginator.py", line 102, in num_pages
    if self.count == 0 and not self.allow_empty_first_page:
  File "/usr/local/lib/python3.10/site-packages/django/utils/functional.py", line 49, in __get__
    res = instance.__dict__[self.name] = self.func(instance)
  File "/usr/local/lib/python3.10/site-packages/django/core/paginator.py", line 96, in count
    return c()
  File "/usr/local/lib/python3.10/site-packages/django/db/models/query.py", line 470, in count
    return self.query.get_count(using=self.db)
  File "/usr/local/lib/python3.10/site-packages/django/db/models/sql/query.py", line 552, in get_count
    number = obj.get_aggregation(using, ["__count"])["__count"]
  File "/usr/local/lib/python3.10/site-packages/django/db/models/sql/query.py", line 537, in get_aggregation
    result = compiler.execute_sql(SINGLE)
  File "/usr/local/lib/python3.10/site-packages/django/db/models/sql/compiler.py", line 1361, in execute_sql
    cursor.execute(sql, params)
  File "/usr/local/lib/python3.10/site-packages/debug_toolbar/panels/sql/tracking.py", line 205, in execute
    return self._record(self.cursor.execute, sql, params)
  File "/usr/local/lib/python3.10/site-packages/debug_toolbar/panels/sql/tracking.py", line 140, in _record
    return method(sql, params)
  File "/usr/local/lib/python3.10/site-packages/django/db/backends/utils.py", line 103, in execute
    return super().execute(sql, params)
  File "/usr/local/lib/python3.10/site-packages/django/db/backends/utils.py", line 67, in execute
    return self._execute_with_wrappers(
  File "/usr/local/lib/python3.10/site-packages/django/db/backends/utils.py", line 80, in _execute_with_wrappers
    return executor(sql, params, many, context)
  File "/usr/local/lib/python3.10/site-packages/django/db/backends/utils.py", line 84, in _execute
    with self.db.wrap_database_errors:
  File "/usr/local/lib/python3.10/site-packages/django/db/utils.py", line 91, in __exit__
    raise dj_exc_value.with_traceback(traceback) from exc_value
  File "/usr/local/lib/python3.10/site-packages/django/db/backends/utils.py", line 89, in _execute
    return self.cursor.execute(sql, params)
django.db.utils.ProgrammingError: relation "books_book" does not exist
LINE 1: SELECT COUNT(*) AS "__count" FROM "books_book" WHERE "books_...
                                          ^

Internal Server Error: /
Traceback (most recent call last):
  File "/usr/local/lib/python3.10/site-packages/django/db/backends/utils.py", line 89, in _execute
    return self.cursor.execute(sql, params)
psycopg2.errors.UndefinedTable: relation "books_book" does not exist
LINE 1: SELECT COUNT(*) AS "__count" FROM "books_book" WHERE "books_...
                                          ^


The above exception was the direct cause of the following exception:

Traceback (most recent call last):
  File "/usr/local/lib/python3.10/site-packages/django/core/handlers/exception.py", line 55, in inner
    response = get_response(request)
  File "/usr/local/lib/python3.10/site-packages/django/core/handlers/base.py", line 197, in _get_response
    response = wrapped_callback(request, *callback_args, **callback_kwargs)
  File "/usr/local/lib/python3.10/site-packages/django/views/generic/base.py", line 84, in view
    return self.dispatch(request, *args, **kwargs)
  File "/usr/local/lib/python3.10/site-packages/django/views/generic/base.py", line 119, in dispatch
    return handler(request, *args, **kwargs)
  File "/usr/local/lib/python3.10/site-packages/django/views/generic/list.py", line 174, in get
    context = self.get_context_data()
  File "/usr/local/lib/python3.10/site-packages/django/views/generic/list.py", line 128, in get_context_data
    paginator, page, queryset, is_paginated = self.paginate_queryset(
  File "/usr/local/lib/python3.10/site-packages/django/views/generic/list.py", line 73, in paginate_queryset
    page = paginator.page(page_number)
  File "/usr/local/lib/python3.10/site-packages/django/core/paginator.py", line 75, in page
    number = self.validate_number(number)
  File "/usr/local/lib/python3.10/site-packages/django/core/paginator.py", line 53, in validate_number
    if number > self.num_pages:
  File "/usr/local/lib/python3.10/site-packages/django/utils/functional.py", line 49, in __get__
    res = instance.__dict__[self.name] = self.func(instance)
  File "/usr/local/lib/python3.10/site-packages/django/core/paginator.py", line 102, in num_pages
    if self.count == 0 and not self.allow_empty_first_page:
  File "/usr/local/lib/python3.10/site-packages/django/utils/functional.py", line 49, in __get__
    res = instance.__dict__[self.name] = self.func(instance)
  File "/usr/local/lib/python3.10/site-packages/django/core/paginator.py", line 96, in count
    return c()
  File "/usr/local/lib/python3.10/site-packages/django/db/models/query.py", line 470, in count
    return self.query.get_count(using=self.db)
  File "/usr/local/lib/python3.10/site-packages/django/db/models/sql/query.py", line 552, in get_count
    number = obj.get_aggregation(using, ["__count"])["__count"]
  File "/usr/local/lib/python3.10/site-packages/django/db/models/sql/query.py", line 537, in get_aggregation
    result = compiler.execute_sql(SINGLE)
  File "/usr/local/lib/python3.10/site-packages/django/db/models/sql/compiler.py", line 1361, in execute_sql
    cursor.execute(sql, params)
  File "/usr/local/lib/python3.10/site-packages/debug_toolbar/panels/sql/tracking.py", line 205, in execute
    return self._record(self.cursor.execute, sql, params)
  File "/usr/local/lib/python3.10/site-packages/debug_toolbar/panels/sql/tracking.py", line 140, in _record
    return method(sql, params)
  File "/usr/local/lib/python3.10/site-packages/django/db/backends/utils.py", line 103, in execute
    return super().execute(sql, params)
  File "/usr/local/lib/python3.10/site-packages/django/db/backends/utils.py", line 67, in execute
    return self._execute_with_wrappers(
  File "/usr/local/lib/python3.10/site-packages/django/db/backends/utils.py", line 80, in _execute_with_wrappers
    return executor(sql, params, many, context)
  File "/usr/local/lib/python3.10/site-packages/django/db/backends/utils.py", line 84, in _execute
    with self.db.wrap_database_errors:
  File "/usr/local/lib/python3.10/site-packages/django/db/utils.py", line 91, in __exit__
    raise dj_exc_value.with_traceback(traceback) from exc_value
  File "/usr/local/lib/python3.10/site-packages/django/db/backends/utils.py", line 89, in _execute
    return self.cursor.execute(sql, params)
django.db.utils.ProgrammingError: relation "books_book" does not exist
LINE 1: SELECT COUNT(*) AS "__count" FROM "books_book" WHERE "books_...
                                          ^

Not Found: /static/images/favicon.png
Not Found: /static/images/favicon.png
Not Found: /d14ae4be-5967-48e2-92d8-f10c5ab1d7e6/delete/
Not Found: /d14ae4be-5967-48e2-92d8-f10c5ab1d7e6/delete/
Not Found: /d14ae4be-5967-48e2-92d8-f10c5ab1d7e6/delete/
Not Found: /d14ae4be-5967-48e2-92d8-f10c5ab1d7e6/delete/
Not Found: /d14ae4be-5967-48e2-92d8-f10c5ab1d7e6/delete/
Not Found: /d14ae4be-5967-48e2-92d8-f10c5ab1d7e6/delete/
Not Found: /d14ae4be-5967-48e2-92d8-f10c5ab1d7e6/delete/
Not Found: /d14ae4be-5967-48e2-92d8-f10c5ab1d7e6/delete/
Not Found: /d14ae4be-5967-48e2-92d8-f10c5ab1d7e6/delete/
Not Found: /d14ae4be-5967-48e2-92d8-f10c5ab1d7e6/delete/
Not Found: /d14ae4be-5967-48e2-92d8-f10c5ab1d7e6/delete/
Not Found: /d14ae4be-5967-48e2-92d8-f10c5ab1d7e6/delete/
Not Found: /d14ae4be-5967-48e2-92d8-f10c5ab1d7e6/delete/
Not Found: /d14ae4be-5967-48e2-92d8-f10c5ab1d7e6/delete/
Not Found: /d14ae4be-5967-48e2-92d8-f10c5ab1d7e6/delete/
Not Found: /d14ae4be-5967-48e2-92d8-f10c5ab1d7e6/delete/
Not Found: /d14ae4be-5967-48e2-92d8-f10c5ab1d7e6/delete/
Not Found: /favicon.ico/
Not Found: /35f7707b-fc59-437a-9153-6da82c5571ad/delete/
Internal Server Error: /
Traceback (most recent call last):
  File "/usr/local/lib/python3.10/site-packages/django/db/backends/utils.py", line 89, in _execute
    return self.cursor.execute(sql, params)
psycopg2.errors.UndefinedTable: relation "books_book" does not exist
LINE 1: SELECT COUNT(*) AS "__count" FROM "books_book" WHERE "books_...
                                          ^


The above exception was the direct cause of the following exception:

Traceback (most recent call last):
  File "/usr/local/lib/python3.10/site-packages/django/core/handlers/exception.py", line 55, in inner
    response = get_response(request)
  File "/usr/local/lib/python3.10/site-packages/django/core/handlers/base.py", line 197, in _get_response
    response = wrapped_callback(request, *callback_args, **callback_kwargs)
  File "/usr/local/lib/python3.10/site-packages/django/views/generic/base.py", line 84, in view
    return self.dispatch(request, *args, **kwargs)
  File "/usr/local/lib/python3.10/site-packages/django/views/generic/base.py", line 119, in dispatch
    return handler(request, *args, **kwargs)
  File "/usr/local/lib/python3.10/site-packages/django/views/generic/list.py", line 174, in get
    context = self.get_context_data()
  File "/usr/local/lib/python3.10/site-packages/django/views/generic/list.py", line 128, in get_context_data
    paginator, page, queryset, is_paginated = self.paginate_queryset(
  File "/usr/local/lib/python3.10/site-packages/django/views/generic/list.py", line 73, in paginate_queryset
    page = paginator.page(page_number)
  File "/usr/local/lib/python3.10/site-packages/django/core/paginator.py", line 75, in page
    number = self.validate_number(number)
  File "/usr/local/lib/python3.10/site-packages/django/core/paginator.py", line 53, in validate_number
    if number > self.num_pages:
  File "/usr/local/lib/python3.10/site-packages/django/utils/functional.py", line 49, in __get__
    res = instance.__dict__[self.name] = self.func(instance)
  File "/usr/local/lib/python3.10/site-packages/django/core/paginator.py", line 102, in num_pages
    if self.count == 0 and not self.allow_empty_first_page:
  File "/usr/local/lib/python3.10/site-packages/django/utils/functional.py", line 49, in __get__
    res = instance.__dict__[self.name] = self.func(instance)
  File "/usr/local/lib/python3.10/site-packages/django/core/paginator.py", line 96, in count
    return c()
  File "/usr/local/lib/python3.10/site-packages/django/db/models/query.py", line 470, in count
    return self.query.get_count(using=self.db)
  File "/usr/local/lib/python3.10/site-packages/django/db/models/sql/query.py", line 552, in get_count
    number = obj.get_aggregation(using, ["__count"])["__count"]
  File "/usr/local/lib/python3.10/site-packages/django/db/models/sql/query.py", line 537, in get_aggregation
    result = compiler.execute_sql(SINGLE)
  File "/usr/local/lib/python3.10/site-packages/django/db/models/sql/compiler.py", line 1361, in execute_sql
    cursor.execute(sql, params)
  File "/usr/local/lib/python3.10/site-packages/debug_toolbar/panels/sql/tracking.py", line 205, in execute
    return self._record(self.cursor.execute, sql, params)
  File "/usr/local/lib/python3.10/site-packages/debug_toolbar/panels/sql/tracking.py", line 140, in _record
    return method(sql, params)
  File "/usr/local/lib/python3.10/site-packages/django/db/backends/utils.py", line 103, in execute
    return super().execute(sql, params)
  File "/usr/local/lib/python3.10/site-packages/django/db/backends/utils.py", line 67, in execute
    return self._execute_with_wrappers(
  File "/usr/local/lib/python3.10/site-packages/django/db/backends/utils.py", line 80, in _execute_with_wrappers
    return executor(sql, params, many, context)
  File "/usr/local/lib/python3.10/site-packages/django/db/backends/utils.py", line 84, in _execute
    with self.db.wrap_database_errors:
  File "/usr/local/lib/python3.10/site-packages/django/db/utils.py", line 91, in __exit__
    raise dj_exc_value.with_traceback(traceback) from exc_value
  File "/usr/local/lib/python3.10/site-packages/django/db/backends/utils.py", line 89, in _execute
    return self.cursor.execute(sql, params)
django.db.utils.ProgrammingError: relation "books_book" does not exist
LINE 1: SELECT COUNT(*) AS "__count" FROM "books_book" WHERE "books_...
                                          ^

Internal Server Error: /
Traceback (most recent call last):
  File "/usr/local/lib/python3.10/site-packages/django/contrib/sessions/backends/base.py", line 187, in _get_session
    return self._session_cache
AttributeError: 'SessionStore' object has no attribute '_session_cache'

During handling of the above exception, another exception occurred:

Traceback (most recent call last):
  File "/usr/local/lib/python3.10/site-packages/django/db/backends/utils.py", line 89, in _execute
    return self.cursor.execute(sql, params)
psycopg2.errors.UndefinedTable: relation "django_session" does not exist
LINE 1: ...ession_data", "django_session"."expire_date" FROM "django_se...
                                                             ^


The above exception was the direct cause of the following exception:

Traceback (most recent call last):
  File "/usr/local/lib/python3.10/site-packages/django/core/handlers/exception.py", line 55, in inner
    response = get_response(request)
  File "/usr/local/lib/python3.10/site-packages/debug_toolbar/middleware.py", line 67, in __call__
    panel.generate_stats(request, response)
  File "/usr/local/lib/python3.10/site-packages/debug_toolbar/panels/request.py", line 66, in generate_stats
    for k in sorted(request.session.keys())
  File "/usr/local/lib/python3.10/site-packages/django/contrib/sessions/backends/base.py", line 123, in keys
    return self._session.keys()
  File "/usr/local/lib/python3.10/site-packages/django/contrib/sessions/backends/base.py", line 192, in _get_session
    self._session_cache = self.load()
  File "/usr/local/lib/python3.10/site-packages/django/contrib/sessions/backends/db.py", line 42, in load
    s = self._get_session_from_db()
  File "/usr/local/lib/python3.10/site-packages/django/contrib/sessions/backends/db.py", line 32, in _get_session_from_db
    return self.model.objects.get(
  File "/usr/local/lib/python3.10/site-packages/django/db/models/manager.py", line 85, in manager_method
    return getattr(self.get_queryset(), name)(*args, **kwargs)
  File "/usr/local/lib/python3.10/site-packages/django/db/models/query.py", line 492, in get
    num = len(clone)
  File "/usr/local/lib/python3.10/site-packages/django/db/models/query.py", line 302, in __len__
    self._fetch_all()
  File "/usr/local/lib/python3.10/site-packages/django/db/models/query.py", line 1507, in _fetch_all
    self._result_cache = list(self._iterable_class(self))
  File "/usr/local/lib/python3.10/site-packages/django/db/models/query.py", line 57, in __iter__
    results = compiler.execute_sql(
  File "/usr/local/lib/python3.10/site-packages/django/db/models/sql/compiler.py", line 1361, in execute_sql
    cursor.execute(sql, params)
  File "/usr/local/lib/python3.10/site-packages/django/db/backends/utils.py", line 103, in execute
    return super().execute(sql, params)
  File "/usr/local/lib/python3.10/site-packages/django/db/backends/utils.py", line 67, in execute
    return self._execute_with_wrappers(
  File "/usr/local/lib/python3.10/site-packages/django/db/backends/utils.py", line 80, in _execute_with_wrappers
    return executor(sql, params, many, context)
  File "/usr/local/lib/python3.10/site-packages/django/db/backends/utils.py", line 84, in _execute
    with self.db.wrap_database_errors:
  File "/usr/local/lib/python3.10/site-packages/django/db/utils.py", line 91, in __exit__
    raise dj_exc_value.with_traceback(traceback) from exc_value
  File "/usr/local/lib/python3.10/site-packages/django/db/backends/utils.py", line 89, in _execute
    return self.cursor.execute(sql, params)
django.db.utils.ProgrammingError: relation "django_session" does not exist
LINE 1: ...ession_data", "django_session"."expire_date" FROM "django_se...
                                                             ^

Internal Server Error: /favicon.ico/
Traceback (most recent call last):
  File "/usr/local/lib/python3.10/site-packages/django/db/backends/utils.py", line 89, in _execute
    return self.cursor.execute(sql, params)
psycopg2.errors.UndefinedTable: relation "accounts_customuser" does not exist
LINE 1: ...omuser"."bio", "accounts_customuser"."email" FROM "accounts_...
                                                             ^


The above exception was the direct cause of the following exception:

Traceback (most recent call last):
  File "/usr/local/lib/python3.10/site-packages/django/core/handlers/exception.py", line 55, in inner
    response = get_response(request)
  File "/usr/local/lib/python3.10/site-packages/django/core/handlers/base.py", line 197, in _get_response
    response = wrapped_callback(request, *callback_args, **callback_kwargs)
  File "/usr/local/lib/python3.10/site-packages/django/views/generic/base.py", line 84, in view
    return self.dispatch(request, *args, **kwargs)
  File "/usr/local/lib/python3.10/site-packages/django/views/generic/base.py", line 119, in dispatch
    return handler(request, *args, **kwargs)
  File "/usr/local/lib/python3.10/site-packages/django/views/generic/list.py", line 154, in get
    self.object_list = self.get_queryset()
  File "/code/books/views.py", line 134, in get_queryset
    user = get_object_or_404(
  File "/usr/local/lib/python3.10/site-packages/django/shortcuts.py", line 85, in get_object_or_404
    return queryset.get(*args, **kwargs)
  File "/usr/local/lib/python3.10/site-packages/django/db/models/query.py", line 492, in get
    num = len(clone)
  File "/usr/local/lib/python3.10/site-packages/django/db/models/query.py", line 302, in __len__
    self._fetch_all()
  File "/usr/local/lib/python3.10/site-packages/django/db/models/query.py", line 1507, in _fetch_all
    self._result_cache = list(self._iterable_class(self))
  File "/usr/local/lib/python3.10/site-packages/django/db/models/query.py", line 57, in __iter__
    results = compiler.execute_sql(
  File "/usr/local/lib/python3.10/site-packages/django/db/models/sql/compiler.py", line 1361, in execute_sql
    cursor.execute(sql, params)
  File "/usr/local/lib/python3.10/site-packages/debug_toolbar/panels/sql/tracking.py", line 205, in execute
    return self._record(self.cursor.execute, sql, params)
  File "/usr/local/lib/python3.10/site-packages/debug_toolbar/panels/sql/tracking.py", line 140, in _record
    return method(sql, params)
  File "/usr/local/lib/python3.10/site-packages/django/db/backends/utils.py", line 103, in execute
    return super().execute(sql, params)
  File "/usr/local/lib/python3.10/site-packages/django/db/backends/utils.py", line 67, in execute
    return self._execute_with_wrappers(
  File "/usr/local/lib/python3.10/site-packages/django/db/backends/utils.py", line 80, in _execute_with_wrappers
    return executor(sql, params, many, context)
  File "/usr/local/lib/python3.10/site-packages/django/db/backends/utils.py", line 84, in _execute
    with self.db.wrap_database_errors:
  File "/usr/local/lib/python3.10/site-packages/django/db/utils.py", line 91, in __exit__
    raise dj_exc_value.with_traceback(traceback) from exc_value
  File "/usr/local/lib/python3.10/site-packages/django/db/backends/utils.py", line 89, in _execute
    return self.cursor.execute(sql, params)
django.db.utils.ProgrammingError: relation "accounts_customuser" does not exist
LINE 1: ...omuser"."bio", "accounts_customuser"."email" FROM "accounts_...
                                                             ^

Internal Server Error: /favicon.ico/
Traceback (most recent call last):
  File "/usr/local/lib/python3.10/site-packages/django/contrib/sessions/backends/base.py", line 187, in _get_session
    return self._session_cache
AttributeError: 'SessionStore' object has no attribute '_session_cache'

During handling of the above exception, another exception occurred:

Traceback (most recent call last):
  File "/usr/local/lib/python3.10/site-packages/django/db/backends/utils.py", line 89, in _execute
    return self.cursor.execute(sql, params)
psycopg2.errors.UndefinedTable: relation "django_session" does not exist
LINE 1: ...ession_data", "django_session"."expire_date" FROM "django_se...
                                                             ^


The above exception was the direct cause of the following exception:

Traceback (most recent call last):
  File "/usr/local/lib/python3.10/site-packages/django/core/handlers/exception.py", line 55, in inner
    response = get_response(request)
  File "/usr/local/lib/python3.10/site-packages/debug_toolbar/middleware.py", line 67, in __call__
    panel.generate_stats(request, response)
  File "/usr/local/lib/python3.10/site-packages/debug_toolbar/panels/request.py", line 66, in generate_stats
    for k in sorted(request.session.keys())
  File "/usr/local/lib/python3.10/site-packages/django/contrib/sessions/backends/base.py", line 123, in keys
    return self._session.keys()
  File "/usr/local/lib/python3.10/site-packages/django/contrib/sessions/backends/base.py", line 192, in _get_session
    self._session_cache = self.load()
  File "/usr/local/lib/python3.10/site-packages/django/contrib/sessions/backends/db.py", line 42, in load
    s = self._get_session_from_db()
  File "/usr/local/lib/python3.10/site-packages/django/contrib/sessions/backends/db.py", line 32, in _get_session_from_db
    return self.model.objects.get(
  File "/usr/local/lib/python3.10/site-packages/django/db/models/manager.py", line 85, in manager_method
    return getattr(self.get_queryset(), name)(*args, **kwargs)
  File "/usr/local/lib/python3.10/site-packages/django/db/models/query.py", line 492, in get
    num = len(clone)
  File "/usr/local/lib/python3.10/site-packages/django/db/models/query.py", line 302, in __len__
    self._fetch_all()
  File "/usr/local/lib/python3.10/site-packages/django/db/models/query.py", line 1507, in _fetch_all
    self._result_cache = list(self._iterable_class(self))
  File "/usr/local/lib/python3.10/site-packages/django/db/models/query.py", line 57, in __iter__
    results = compiler.execute_sql(
  File "/usr/local/lib/python3.10/site-packages/django/db/models/sql/compiler.py", line 1361, in execute_sql
    cursor.execute(sql, params)
  File "/usr/local/lib/python3.10/site-packages/django/db/backends/utils.py", line 103, in execute
    return super().execute(sql, params)
  File "/usr/local/lib/python3.10/site-packages/django/db/backends/utils.py", line 67, in execute
    return self._execute_with_wrappers(
  File "/usr/local/lib/python3.10/site-packages/django/db/backends/utils.py", line 80, in _execute_with_wrappers
    return executor(sql, params, many, context)
  File "/usr/local/lib/python3.10/site-packages/django/db/backends/utils.py", line 84, in _execute
    with self.db.wrap_database_errors:
  File "/usr/local/lib/python3.10/site-packages/django/db/utils.py", line 91, in __exit__
    raise dj_exc_value.with_traceback(traceback) from exc_value
  File "/usr/local/lib/python3.10/site-packages/django/db/backends/utils.py", line 89, in _execute
    return self.cursor.execute(sql, params)
django.db.utils.ProgrammingError: relation "django_session" does not exist
LINE 1: ...ession_data", "django_session"."expire_date" FROM "django_se...
                                                             ^

Not Found: /static/images/favicon.png
Watching for file changes with StatReloader
Watching for file changes with StatReloader
Watching for file changes with StatReloader
Watching for file changes with StatReloader
/code/config/urls.py changed, reloading.
Watching for file changes with StatReloader
Not Found: /favicon.ico/
/code/books/models.py changed, reloading.
Watching for file changes with StatReloader
/code/books/models.py changed, reloading.
Watching for file changes with StatReloader
/code/books/models.py changed, reloading.
Watching for file changes with StatReloader
/code/books/models.py changed, reloading.
Watching for file changes with StatReloader
/code/books/models.py changed, reloading.
Watching for file changes with StatReloader
/code/books/models.py changed, reloading.
Watching for file changes with StatReloader
/code/books/models.py changed, reloading.
Watching for file changes with StatReloader
/code/books/models.py changed, reloading.
Watching for file changes with StatReloader
Internal Server Error: /create/
Traceback (most recent call last):
  File "/code/books/models.py", line 52, in save
    self.pages=pages(self.pdf.name)
  File "/code/books/models.py", line 23, in pages
    with open(url, 'rb') as file:
FileNotFoundError: [Errno 2] No such file or directory: 'book/pdfs/Architectural_pattern_1nthxHD.pdf'

During handling of the above exception, another exception occurred:

Traceback (most recent call last):
  File "/usr/local/lib/python3.10/site-packages/django/core/handlers/exception.py", line 55, in inner
    response = get_response(request)
  File "/usr/local/lib/python3.10/site-packages/django/core/handlers/base.py", line 197, in _get_response
    response = wrapped_callback(request, *callback_args, **callback_kwargs)
  File "/usr/local/lib/python3.10/site-packages/django/views/generic/base.py", line 84, in view
    return self.dispatch(request, *args, **kwargs)
  File "/usr/local/lib/python3.10/site-packages/django/contrib/auth/mixins.py", line 73, in dispatch
    return super().dispatch(request, *args, **kwargs)
  File "/usr/local/lib/python3.10/site-packages/django/views/generic/base.py", line 119, in dispatch
    return handler(request, *args, **kwargs)
  File "/usr/local/lib/python3.10/site-packages/django/views/generic/edit.py", line 184, in post
    return super().post(request, *args, **kwargs)
  File "/usr/local/lib/python3.10/site-packages/django/views/generic/edit.py", line 153, in post
    return self.form_valid(form)
  File "/code/books/views.py", line 28, in form_valid
    return super().form_valid(form)
  File "/usr/local/lib/python3.10/site-packages/django/views/generic/edit.py", line 135, in form_valid
    self.object = form.save()
  File "/usr/local/lib/python3.10/site-packages/django/forms/models.py", line 548, in save
    self.instance.save()
  File "/code/books/models.py", line 55, in save
    book= Book.objects.get(id =self.id)
  File "/usr/local/lib/python3.10/site-packages/django/db/models/manager.py", line 85, in manager_method
    return getattr(self.get_queryset(), name)(*args, **kwargs)
  File "/usr/local/lib/python3.10/site-packages/django/db/models/query.py", line 496, in get
    raise self.model.DoesNotExist(
books.models.Book.DoesNotExist: Book matching query does not exist.
Not Found: /favicon.ico/
Internal Server Error: /create/
Traceback (most recent call last):
  File "/code/books/models.py", line 52, in save
    self.pages=pages(self.pdf.name)
  File "/code/books/models.py", line 23, in pages
    with open(url, 'r') as file:
FileNotFoundError: [Errno 2] No such file or directory: 'book/pdfs/Architectural_pattern_4JUwWrg.pdf'

During handling of the above exception, another exception occurred:

Traceback (most recent call last):
  File "/usr/local/lib/python3.10/site-packages/django/core/handlers/exception.py", line 55, in inner
    response = get_response(request)
  File "/usr/local/lib/python3.10/site-packages/django/core/handlers/base.py", line 197, in _get_response
    response = wrapped_callback(request, *callback_args, **callback_kwargs)
  File "/usr/local/lib/python3.10/site-packages/django/views/generic/base.py", line 84, in view
    return self.dispatch(request, *args, **kwargs)
  File "/usr/local/lib/python3.10/site-packages/django/contrib/auth/mixins.py", line 73, in dispatch
    return super().dispatch(request, *args, **kwargs)
  File "/usr/local/lib/python3.10/site-packages/django/views/generic/base.py", line 119, in dispatch
    return handler(request, *args, **kwargs)
  File "/usr/local/lib/python3.10/site-packages/django/views/generic/edit.py", line 184, in post
    return super().post(request, *args, **kwargs)
  File "/usr/local/lib/python3.10/site-packages/django/views/generic/edit.py", line 153, in post
    return self.form_valid(form)
  File "/code/books/views.py", line 28, in form_valid
    return super().form_valid(form)
  File "/usr/local/lib/python3.10/site-packages/django/views/generic/edit.py", line 135, in form_valid
    self.object = form.save()
  File "/usr/local/lib/python3.10/site-packages/django/forms/models.py", line 548, in save
    self.instance.save()
  File "/code/books/models.py", line 55, in save
    book= Book.objects.get(id =self.id)
  File "/usr/local/lib/python3.10/site-packages/django/db/models/manager.py", line 85, in manager_method
    return getattr(self.get_queryset(), name)(*args, **kwargs)
  File "/usr/local/lib/python3.10/site-packages/django/db/models/query.py", line 496, in get
    raise self.model.DoesNotExist(
books.models.Book.DoesNotExist: Book matching query does not exist.
Internal Server Error: /create/
Traceback (most recent call last):
  File "/code/books/models.py", line 52, in save
    self.pages=pages(self.pdf.path)
  File "/code/books/models.py", line 23, in pages
    with open(url, 'r') as file:
FileNotFoundError: [Errno 2] No such file or directory: 'book/pdfs/Architectural_pattern_o3Y4Dov.pdf'

During handling of the above exception, another exception occurred:

Traceback (most recent call last):
  File "/usr/local/lib/python3.10/site-packages/django/core/handlers/exception.py", line 55, in inner
    response = get_response(request)
  File "/usr/local/lib/python3.10/site-packages/django/core/handlers/base.py", line 197, in _get_response
    response = wrapped_callback(request, *callback_args, **callback_kwargs)
  File "/usr/local/lib/python3.10/site-packages/django/views/generic/base.py", line 84, in view
    return self.dispatch(request, *args, **kwargs)
  File "/usr/local/lib/python3.10/site-packages/django/contrib/auth/mixins.py", line 73, in dispatch
    return super().dispatch(request, *args, **kwargs)
  File "/usr/local/lib/python3.10/site-packages/django/views/generic/base.py", line 119, in dispatch
    return handler(request, *args, **kwargs)
  File "/usr/local/lib/python3.10/site-packages/django/views/generic/edit.py", line 184, in post
    return super().post(request, *args, **kwargs)
  File "/usr/local/lib/python3.10/site-packages/django/views/generic/edit.py", line 153, in post
    return self.form_valid(form)
  File "/code/books/views.py", line 28, in form_valid
    return super().form_valid(form)
  File "/usr/local/lib/python3.10/site-packages/django/views/generic/edit.py", line 135, in form_valid
    self.object = form.save()
  File "/usr/local/lib/python3.10/site-packages/django/forms/models.py", line 548, in save
    self.instance.save()
  File "/code/books/models.py", line 55, in save
    book= Book.objects.get(id =self.id)
  File "/usr/local/lib/python3.10/site-packages/django/db/models/manager.py", line 85, in manager_method
    return getattr(self.get_queryset(), name)(*args, **kwargs)
  File "/usr/local/lib/python3.10/site-packages/django/db/models/query.py", line 496, in get
    raise self.model.DoesNotExist(
books.models.Book.DoesNotExist: Book matching query does not exist.
Internal Server Error: /profile/
Traceback (most recent call last):
  File "/usr/local/lib/python3.10/site-packages/django/core/handlers/exception.py", line 55, in inner
    response = get_response(request)
  File "/usr/local/lib/python3.10/site-packages/django/core/handlers/base.py", line 220, in _get_response
    response = response.render()
  File "/usr/local/lib/python3.10/site-packages/django/template/response.py", line 114, in render
    self.content = self.rendered_content
  File "/usr/local/lib/python3.10/site-packages/django/template/response.py", line 92, in rendered_content
    return template.render(context, self._request)
  File "/usr/local/lib/python3.10/site-packages/django/template/backends/django.py", line 62, in render
    return self.template.render(context)
  File "/usr/local/lib/python3.10/site-packages/django/template/base.py", line 175, in render
    return self._render(context)
  File "/usr/local/lib/python3.10/site-packages/django/test/utils.py", line 111, in instrumented_test_render
    return self.nodelist.render(context)
  File "/usr/local/lib/python3.10/site-packages/django/template/base.py", line 1000, in render
    return SafeString("".join([node.render_annotated(context) for node in self]))
  File "/usr/local/lib/python3.10/site-packages/django/template/base.py", line 1000, in <listcomp>
    return SafeString("".join([node.render_annotated(context) for node in self]))
  File "/usr/local/lib/python3.10/site-packages/django/template/base.py", line 958, in render_annotated
    return self.render(context)
  File "/usr/local/lib/python3.10/site-packages/django/template/loader_tags.py", line 157, in render
    return compiled_parent._render(context)
  File "/usr/local/lib/python3.10/site-packages/django/test/utils.py", line 111, in instrumented_test_render
    return self.nodelist.render(context)
  File "/usr/local/lib/python3.10/site-packages/django/template/base.py", line 1000, in render
    return SafeString("".join([node.render_annotated(context) for node in self]))
  File "/usr/local/lib/python3.10/site-packages/django/template/base.py", line 1000, in <listcomp>
    return SafeString("".join([node.render_annotated(context) for node in self]))
  File "/usr/local/lib/python3.10/site-packages/django/template/base.py", line 958, in render_annotated
    return self.render(context)
  File "/usr/local/lib/python3.10/site-packages/django/template/loader_tags.py", line 63, in render
    result = block.nodelist.render(context)
  File "/usr/local/lib/python3.10/site-packages/django/template/base.py", line 1000, in render
    return SafeString("".join([node.render_annotated(context) for node in self]))
  File "/usr/local/lib/python3.10/site-packages/django/template/base.py", line 1000, in <listcomp>
    return SafeString("".join([node.render_annotated(context) for node in self]))
  File "/usr/local/lib/python3.10/site-packages/django/template/base.py", line 958, in render_annotated
    return self.render(context)
  File "/usr/local/lib/python3.10/site-packages/django/template/defaulttags.py", line 322, in render
    return nodelist.render(context)
  File "/usr/local/lib/python3.10/site-packages/django/template/base.py", line 1000, in render
    return SafeString("".join([node.render_annotated(context) for node in self]))
  File "/usr/local/lib/python3.10/site-packages/django/template/base.py", line 1000, in <listcomp>
    return SafeString("".join([node.render_annotated(context) for node in self]))
  File "/usr/local/lib/python3.10/site-packages/django/template/base.py", line 958, in render_annotated
    return self.render(context)
  File "/usr/local/lib/python3.10/site-packages/django/template/loader_tags.py", line 208, in render
    return template.render(context)
  File "/usr/local/lib/python3.10/site-packages/django/template/base.py", line 177, in render
    return self._render(context)
  File "/usr/local/lib/python3.10/site-packages/django/test/utils.py", line 111, in instrumented_test_render
    return self.nodelist.render(context)
  File "/usr/local/lib/python3.10/site-packages/django/template/base.py", line 1000, in render
    return SafeString("".join([node.render_annotated(context) for node in self]))
  File "/usr/local/lib/python3.10/site-packages/django/template/base.py", line 1000, in <listcomp>
    return SafeString("".join([node.render_annotated(context) for node in self]))
  File "/usr/local/lib/python3.10/site-packages/django/template/base.py", line 958, in render_annotated
    return self.render(context)
  File "/usr/local/lib/python3.10/site-packages/django/template/defaulttags.py", line 238, in render
    nodelist.append(node.render_annotated(context))
  File "/usr/local/lib/python3.10/site-packages/django/template/base.py", line 958, in render_annotated
    return self.render(context)
  File "/usr/local/lib/python3.10/site-packages/django/template/defaulttags.py", line 472, in render
    url = reverse(view_name, args=args, kwargs=kwargs, current_app=current_app)
  File "/usr/local/lib/python3.10/site-packages/django/urls/base.py", line 88, in reverse
    return resolver._reverse_with_prefix(view, prefix, *args, **kwargs)
  File "/usr/local/lib/python3.10/site-packages/django/urls/resolvers.py", line 802, in _reverse_with_prefix
    raise NoReverseMatch(msg)
django.urls.exceptions.NoReverseMatch: Reverse for 'download' not found. 'download' is not a valid view function or pattern name.
Not Found: /static/images/favicon.png
Internal Server Error: /create/
Traceback (most recent call last):
  File "/usr/local/lib/python3.10/site-packages/django/core/handlers/exception.py", line 55, in inner
    response = get_response(request)
  File "/usr/local/lib/python3.10/site-packages/django/core/handlers/base.py", line 197, in _get_response
    response = wrapped_callback(request, *callback_args, **callback_kwargs)
  File "/usr/local/lib/python3.10/site-packages/django/views/generic/base.py", line 84, in view
    return self.dispatch(request, *args, **kwargs)
  File "/usr/local/lib/python3.10/site-packages/django/contrib/auth/mixins.py", line 73, in dispatch
    return super().dispatch(request, *args, **kwargs)
  File "/usr/local/lib/python3.10/site-packages/django/views/generic/base.py", line 119, in dispatch
    return handler(request, *args, **kwargs)
  File "/usr/local/lib/python3.10/site-packages/django/views/generic/edit.py", line 180, in get
    return super().get(request, *args, **kwargs)
  File "/usr/local/lib/python3.10/site-packages/django/views/generic/edit.py", line 144, in get
    return self.render_to_response(self.get_context_data())
  File "/usr/local/lib/python3.10/site-packages/django/views/generic/edit.py", line 74, in get_context_data
    kwargs["form"] = self.get_form()
  File "/usr/local/lib/python3.10/site-packages/django/views/generic/edit.py", line 39, in get_form
    return form_class(**self.get_form_kwargs())
  File "/usr/local/lib/python3.10/site-packages/django/forms/models.py", line 356, in __init__
    raise ValueError("ModelForm has no model class specified.")
ValueError: ModelForm has no model class specified.
Internal Server Error: /create/
Traceback (most recent call last):
  File "/usr/local/lib/python3.10/site-packages/django/core/handlers/exception.py", line 55, in inner
    response = get_response(request)
  File "/usr/local/lib/python3.10/site-packages/django/core/handlers/base.py", line 197, in _get_response
    response = wrapped_callback(request, *callback_args, **callback_kwargs)
  File "/usr/local/lib/python3.10/site-packages/django/views/generic/base.py", line 84, in view
    return self.dispatch(request, *args, **kwargs)
  File "/usr/local/lib/python3.10/site-packages/django/contrib/auth/mixins.py", line 73, in dispatch
    return super().dispatch(request, *args, **kwargs)
  File "/usr/local/lib/python3.10/site-packages/django/views/generic/base.py", line 119, in dispatch
    return handler(request, *args, **kwargs)
  File "/usr/local/lib/python3.10/site-packages/django/views/generic/edit.py", line 180, in get
    return super().get(request, *args, **kwargs)
  File "/usr/local/lib/python3.10/site-packages/django/views/generic/edit.py", line 144, in get
    return self.render_to_response(self.get_context_data())
  File "/usr/local/lib/python3.10/site-packages/django/views/generic/edit.py", line 74, in get_context_data
    kwargs["form"] = self.get_form()
  File "/usr/local/lib/python3.10/site-packages/django/views/generic/edit.py", line 39, in get_form
    return form_class(**self.get_form_kwargs())
  File "/usr/local/lib/python3.10/site-packages/django/forms/models.py", line 356, in __init__
    raise ValueError("ModelForm has no model class specified.")
ValueError: ModelForm has no model class specified.
Internal Server Error: /create/
Traceback (most recent call last):
  File "/usr/local/lib/python3.10/site-packages/django/core/handlers/exception.py", line 55, in inner
    response = get_response(request)
  File "/usr/local/lib/python3.10/site-packages/django/core/handlers/base.py", line 197, in _get_response
    response = wrapped_callback(request, *callback_args, **callback_kwargs)
  File "/usr/local/lib/python3.10/site-packages/django/views/generic/base.py", line 84, in view
    return self.dispatch(request, *args, **kwargs)
  File "/usr/local/lib/python3.10/site-packages/django/contrib/auth/mixins.py", line 73, in dispatch
    return super().dispatch(request, *args, **kwargs)
  File "/usr/local/lib/python3.10/site-packages/django/views/generic/base.py", line 119, in dispatch
    return handler(request, *args, **kwargs)
  File "/usr/local/lib/python3.10/site-packages/django/views/generic/edit.py", line 180, in get
    return super().get(request, *args, **kwargs)
  File "/usr/local/lib/python3.10/site-packages/django/views/generic/edit.py", line 144, in get
    return self.render_to_response(self.get_context_data())
  File "/usr/local/lib/python3.10/site-packages/django/views/generic/edit.py", line 74, in get_context_data
    kwargs["form"] = self.get_form()
  File "/usr/local/lib/python3.10/site-packages/django/views/generic/edit.py", line 39, in get_form
    return form_class(**self.get_form_kwargs())
  File "/usr/local/lib/python3.10/site-packages/django/forms/models.py", line 356, in __init__
    raise ValueError("ModelForm has no model class specified.")
ValueError: ModelForm has no model class specified.
Internal Server Error: /create/
Traceback (most recent call last):
  File "/usr/local/lib/python3.10/site-packages/django/core/handlers/exception.py", line 55, in inner
    response = get_response(request)
  File "/usr/local/lib/python3.10/site-packages/django/core/handlers/base.py", line 197, in _get_response
    response = wrapped_callback(request, *callback_args, **callback_kwargs)
  File "/usr/local/lib/python3.10/site-packages/django/views/generic/base.py", line 84, in view
    return self.dispatch(request, *args, **kwargs)
  File "/usr/local/lib/python3.10/site-packages/django/contrib/auth/mixins.py", line 73, in dispatch
    return super().dispatch(request, *args, **kwargs)
  File "/usr/local/lib/python3.10/site-packages/django/views/generic/base.py", line 119, in dispatch
    return handler(request, *args, **kwargs)
  File "/usr/local/lib/python3.10/site-packages/django/views/generic/edit.py", line 180, in get
    return super().get(request, *args, **kwargs)
  File "/usr/local/lib/python3.10/site-packages/django/views/generic/edit.py", line 144, in get
    return self.render_to_response(self.get_context_data())
  File "/usr/local/lib/python3.10/site-packages/django/views/generic/edit.py", line 74, in get_context_data
    kwargs["form"] = self.get_form()
  File "/usr/local/lib/python3.10/site-packages/django/views/generic/edit.py", line 39, in get_form
    return form_class(**self.get_form_kwargs())
  File "/usr/local/lib/python3.10/site-packages/django/forms/models.py", line 356, in __init__
    raise ValueError("ModelForm has no model class specified.")
ValueError: ModelForm has no model class specified.
Internal Server Error: /create/
Traceback (most recent call last):
  File "/usr/local/lib/python3.10/site-packages/django/core/handlers/exception.py", line 55, in inner
    response = get_response(request)
  File "/usr/local/lib/python3.10/site-packages/django/core/handlers/base.py", line 204, in _get_response
    self.check_response(response, callback)
  File "/usr/local/lib/python3.10/site-packages/django/core/handlers/base.py", line 332, in check_response
    raise ValueError(
ValueError: The view books.views.view didn't return an HttpResponse object. It returned None instead.
Internal Server Error: /profile/
Traceback (most recent call last):
  File "/usr/local/lib/python3.10/site-packages/django/template/base.py", line 875, in _resolve_lookup
    current = current[bit]
TypeError: 'ImageFieldFile' object is not subscriptable

During handling of the above exception, another exception occurred:

Traceback (most recent call last):
  File "/usr/local/lib/python3.10/site-packages/django/core/handlers/exception.py", line 55, in inner
    response = get_response(request)
  File "/usr/local/lib/python3.10/site-packages/django/core/handlers/base.py", line 220, in _get_response
    response = response.render()
  File "/usr/local/lib/python3.10/site-packages/django/template/response.py", line 114, in render
    self.content = self.rendered_content
  File "/usr/local/lib/python3.10/site-packages/django/template/response.py", line 92, in rendered_content
    return template.render(context, self._request)
  File "/usr/local/lib/python3.10/site-packages/django/template/backends/django.py", line 62, in render
    return self.template.render(context)
  File "/usr/local/lib/python3.10/site-packages/django/template/base.py", line 175, in render
    return self._render(context)
  File "/usr/local/lib/python3.10/site-packages/django/test/utils.py", line 111, in instrumented_test_render
    return self.nodelist.render(context)
  File "/usr/local/lib/python3.10/site-packages/django/template/base.py", line 1000, in render
    return SafeString("".join([node.render_annotated(context) for node in self]))
  File "/usr/local/lib/python3.10/site-packages/django/template/base.py", line 1000, in <listcomp>
    return SafeString("".join([node.render_annotated(context) for node in self]))
  File "/usr/local/lib/python3.10/site-packages/django/template/base.py", line 958, in render_annotated
    return self.render(context)
  File "/usr/local/lib/python3.10/site-packages/django/template/loader_tags.py", line 157, in render
    return compiled_parent._render(context)
  File "/usr/local/lib/python3.10/site-packages/django/test/utils.py", line 111, in instrumented_test_render
    return self.nodelist.render(context)
  File "/usr/local/lib/python3.10/site-packages/django/template/base.py", line 1000, in render
    return SafeString("".join([node.render_annotated(context) for node in self]))
  File "/usr/local/lib/python3.10/site-packages/django/template/base.py", line 1000, in <listcomp>
    return SafeString("".join([node.render_annotated(context) for node in self]))
  File "/usr/local/lib/python3.10/site-packages/django/template/base.py", line 958, in render_annotated
    return self.render(context)
  File "/usr/local/lib/python3.10/site-packages/django/template/loader_tags.py", line 63, in render
    result = block.nodelist.render(context)
  File "/usr/local/lib/python3.10/site-packages/django/template/base.py", line 1000, in render
    return SafeString("".join([node.render_annotated(context) for node in self]))
  File "/usr/local/lib/python3.10/site-packages/django/template/base.py", line 1000, in <listcomp>
    return SafeString("".join([node.render_annotated(context) for node in self]))
  File "/usr/local/lib/python3.10/site-packages/django/template/base.py", line 958, in render_annotated
    return self.render(context)
  File "/usr/local/lib/python3.10/site-packages/django/template/defaulttags.py", line 322, in render
    return nodelist.render(context)
  File "/usr/local/lib/python3.10/site-packages/django/template/base.py", line 1000, in render
    return SafeString("".join([node.render_annotated(context) for node in self]))
  File "/usr/local/lib/python3.10/site-packages/django/template/base.py", line 1000, in <listcomp>
    return SafeString("".join([node.render_annotated(context) for node in self]))
  File "/usr/local/lib/python3.10/site-packages/django/template/base.py", line 958, in render_annotated
    return self.render(context)
  File "/usr/local/lib/python3.10/site-packages/django/template/loader_tags.py", line 208, in render
    return template.render(context)
  File "/usr/local/lib/python3.10/site-packages/django/template/base.py", line 177, in render
    return self._render(context)
  File "/usr/local/lib/python3.10/site-packages/django/test/utils.py", line 111, in instrumented_test_render
    return self.nodelist.render(context)
  File "/usr/local/lib/python3.10/site-packages/django/template/base.py", line 1000, in render
    return SafeString("".join([node.render_annotated(context) for node in self]))
  File "/usr/local/lib/python3.10/site-packages/django/template/base.py", line 1000, in <listcomp>
    return SafeString("".join([node.render_annotated(context) for node in self]))
  File "/usr/local/lib/python3.10/site-packages/django/template/base.py", line 958, in render_annotated
    return self.render(context)
  File "/usr/local/lib/python3.10/site-packages/django/template/defaulttags.py", line 238, in render
    nodelist.append(node.render_annotated(context))
  File "/usr/local/lib/python3.10/site-packages/django/template/base.py", line 958, in render_annotated
    return self.render(context)
  File "/usr/local/lib/python3.10/site-packages/django/template/base.py", line 1059, in render
    output = self.filter_expression.resolve(context)
  File "/usr/local/lib/python3.10/site-packages/django/template/base.py", line 712, in resolve
    obj = self.var.resolve(context)
  File "/usr/local/lib/python3.10/site-packages/django/template/base.py", line 842, in resolve
    value = self._resolve_lookup(context)
  File "/usr/local/lib/python3.10/site-packages/django/template/base.py", line 885, in _resolve_lookup
    current = getattr(current, bit)
  File "/usr/local/lib/python3.10/site-packages/django/db/models/fields/files.py", line 65, in url
    self._require_file()
  File "/usr/local/lib/python3.10/site-packages/django/db/models/fields/files.py", line 40, in _require_file
    raise ValueError(
ValueError: The 'cover' attribute has no file associated with it.
Internal Server Error: /profile/
Traceback (most recent call last):
  File "/usr/local/lib/python3.10/site-packages/django/template/base.py", line 875, in _resolve_lookup
    current = current[bit]
TypeError: 'ImageFieldFile' object is not subscriptable

During handling of the above exception, another exception occurred:

Traceback (most recent call last):
  File "/usr/local/lib/python3.10/site-packages/django/core/handlers/exception.py", line 55, in inner
    response = get_response(request)
  File "/usr/local/lib/python3.10/site-packages/django/core/handlers/base.py", line 220, in _get_response
    response = response.render()
  File "/usr/local/lib/python3.10/site-packages/django/template/response.py", line 114, in render
    self.content = self.rendered_content
  File "/usr/local/lib/python3.10/site-packages/django/template/response.py", line 92, in rendered_content
    return template.render(context, self._request)
  File "/usr/local/lib/python3.10/site-packages/django/template/backends/django.py", line 62, in render
    return self.template.render(context)
  File "/usr/local/lib/python3.10/site-packages/django/template/base.py", line 175, in render
    return self._render(context)
  File "/usr/local/lib/python3.10/site-packages/django/test/utils.py", line 111, in instrumented_test_render
    return self.nodelist.render(context)
  File "/usr/local/lib/python3.10/site-packages/django/template/base.py", line 1000, in render
    return SafeString("".join([node.render_annotated(context) for node in self]))
  File "/usr/local/lib/python3.10/site-packages/django/template/base.py", line 1000, in <listcomp>
    return SafeString("".join([node.render_annotated(context) for node in self]))
  File "/usr/local/lib/python3.10/site-packages/django/template/base.py", line 958, in render_annotated
    return self.render(context)
  File "/usr/local/lib/python3.10/site-packages/django/template/loader_tags.py", line 157, in render
    return compiled_parent._render(context)
  File "/usr/local/lib/python3.10/site-packages/django/test/utils.py", line 111, in instrumented_test_render
    return self.nodelist.render(context)
  File "/usr/local/lib/python3.10/site-packages/django/template/base.py", line 1000, in render
    return SafeString("".join([node.render_annotated(context) for node in self]))
  File "/usr/local/lib/python3.10/site-packages/django/template/base.py", line 1000, in <listcomp>
    return SafeString("".join([node.render_annotated(context) for node in self]))
  File "/usr/local/lib/python3.10/site-packages/django/template/base.py", line 958, in render_annotated
    return self.render(context)
  File "/usr/local/lib/python3.10/site-packages/django/template/loader_tags.py", line 63, in render
    result = block.nodelist.render(context)
  File "/usr/local/lib/python3.10/site-packages/django/template/base.py", line 1000, in render
    return SafeString("".join([node.render_annotated(context) for node in self]))
  File "/usr/local/lib/python3.10/site-packages/django/template/base.py", line 1000, in <listcomp>
    return SafeString("".join([node.render_annotated(context) for node in self]))
  File "/usr/local/lib/python3.10/site-packages/django/template/base.py", line 958, in render_annotated
    return self.render(context)
  File "/usr/local/lib/python3.10/site-packages/django/template/defaulttags.py", line 322, in render
    return nodelist.render(context)
  File "/usr/local/lib/python3.10/site-packages/django/template/base.py", line 1000, in render
    return SafeString("".join([node.render_annotated(context) for node in self]))
  File "/usr/local/lib/python3.10/site-packages/django/template/base.py", line 1000, in <listcomp>
    return SafeString("".join([node.render_annotated(context) for node in self]))
  File "/usr/local/lib/python3.10/site-packages/django/template/base.py", line 958, in render_annotated
    return self.render(context)
  File "/usr/local/lib/python3.10/site-packages/django/template/loader_tags.py", line 208, in render
    return template.render(context)
  File "/usr/local/lib/python3.10/site-packages/django/template/base.py", line 177, in render
    return self._render(context)
  File "/usr/local/lib/python3.10/site-packages/django/test/utils.py", line 111, in instrumented_test_render
    return self.nodelist.render(context)
  File "/usr/local/lib/python3.10/site-packages/django/template/base.py", line 1000, in render
    return SafeString("".join([node.render_annotated(context) for node in self]))
  File "/usr/local/lib/python3.10/site-packages/django/template/base.py", line 1000, in <listcomp>
    return SafeString("".join([node.render_annotated(context) for node in self]))
  File "/usr/local/lib/python3.10/site-packages/django/template/base.py", line 958, in render_annotated
    return self.render(context)
  File "/usr/local/lib/python3.10/site-packages/django/template/defaulttags.py", line 238, in render
    nodelist.append(node.render_annotated(context))
  File "/usr/local/lib/python3.10/site-packages/django/template/base.py", line 958, in render_annotated
    return self.render(context)
  File "/usr/local/lib/python3.10/site-packages/django/template/base.py", line 1059, in render
    output = self.filter_expression.resolve(context)
  File "/usr/local/lib/python3.10/site-packages/django/template/base.py", line 712, in resolve
    obj = self.var.resolve(context)
  File "/usr/local/lib/python3.10/site-packages/django/template/base.py", line 842, in resolve
    value = self._resolve_lookup(context)
  File "/usr/local/lib/python3.10/site-packages/django/template/base.py", line 885, in _resolve_lookup
    current = getattr(current, bit)
  File "/usr/local/lib/python3.10/site-packages/django/db/models/fields/files.py", line 65, in url
    self._require_file()
  File "/usr/local/lib/python3.10/site-packages/django/db/models/fields/files.py", line 40, in _require_file
    raise ValueError(
ValueError: The 'cover' attribute has no file associated with it.
Internal Server Error: /accounts/1/edit/
Traceback (most recent call last):
  File "/usr/local/lib/python3.10/site-packages/django/core/handlers/exception.py", line 55, in inner
    response = get_response(request)
  File "/usr/local/lib/python3.10/site-packages/django/core/handlers/base.py", line 197, in _get_response
    response = wrapped_callback(request, *callback_args, **callback_kwargs)
  File "/usr/local/lib/python3.10/site-packages/django/views/generic/base.py", line 84, in view
    return self.dispatch(request, *args, **kwargs)
  File "/usr/local/lib/python3.10/site-packages/django/contrib/auth/mixins.py", line 73, in dispatch
    return super().dispatch(request, *args, **kwargs)
  File "/usr/local/lib/python3.10/site-packages/django/contrib/auth/mixins.py", line 132, in dispatch
    user_test_result = self.get_test_func()()
  File "/code/accounts/views.py", line 20, in test_func
    user = self.get_object()
  File "/usr/local/lib/python3.10/site-packages/django/views/generic/detail.py", line 31, in get_object
    queryset = self.get_queryset()
  File "/usr/local/lib/python3.10/site-packages/django/views/generic/detail.py", line 72, in get_queryset
    raise ImproperlyConfigured(
django.core.exceptions.ImproperlyConfigured: ProfileUpdateView is missing a QuerySet. Define ProfileUpdateView.model, ProfileUpdateView.queryset, or override ProfileUpdateView.get_queryset().
Internal Server Error: /accounts/1/edit/
Traceback (most recent call last):
  File "/usr/local/lib/python3.10/site-packages/django/core/handlers/exception.py", line 55, in inner
    response = get_response(request)
  File "/usr/local/lib/python3.10/site-packages/django/core/handlers/base.py", line 197, in _get_response
    response = wrapped_callback(request, *callback_args, **callback_kwargs)
  File "/usr/local/lib/python3.10/site-packages/django/views/generic/base.py", line 84, in view
    return self.dispatch(request, *args, **kwargs)
  File "/usr/local/lib/python3.10/site-packages/django/contrib/auth/mixins.py", line 73, in dispatch
    return super().dispatch(request, *args, **kwargs)
  File "/usr/local/lib/python3.10/site-packages/django/contrib/auth/mixins.py", line 132, in dispatch
    user_test_result = self.get_test_func()()
  File "/code/accounts/views.py", line 20, in test_func
    user = self.get_object()
  File "/usr/local/lib/python3.10/site-packages/django/views/generic/detail.py", line 31, in get_object
    queryset = self.get_queryset()
  File "/usr/local/lib/python3.10/site-packages/django/views/generic/detail.py", line 72, in get_queryset
    raise ImproperlyConfigured(
django.core.exceptions.ImproperlyConfigured: ProfileUpdateView is missing a QuerySet. Define ProfileUpdateView.model, ProfileUpdateView.queryset, or override ProfileUpdateView.get_queryset().
Internal Server Error: /accounts/1/edit/
Traceback (most recent call last):
  File "/usr/local/lib/python3.10/site-packages/django/core/handlers/exception.py", line 55, in inner
    response = get_response(request)
  File "/usr/local/lib/python3.10/site-packages/django/core/handlers/base.py", line 197, in _get_response
    response = wrapped_callback(request, *callback_args, **callback_kwargs)
  File "/usr/local/lib/python3.10/site-packages/django/views/generic/base.py", line 84, in view
    return self.dispatch(request, *args, **kwargs)
  File "/usr/local/lib/python3.10/site-packages/django/contrib/auth/mixins.py", line 73, in dispatch
    return super().dispatch(request, *args, **kwargs)
  File "/usr/local/lib/python3.10/site-packages/django/contrib/auth/mixins.py", line 132, in dispatch
    user_test_result = self.get_test_func()()
  File "/code/accounts/views.py", line 20, in test_func
    user = self.get_object()
  File "/usr/local/lib/python3.10/site-packages/django/views/generic/detail.py", line 31, in get_object
    queryset = self.get_queryset()
  File "/usr/local/lib/python3.10/site-packages/django/views/generic/detail.py", line 72, in get_queryset
    raise ImproperlyConfigured(
django.core.exceptions.ImproperlyConfigured: ProfileUpdateView is missing a QuerySet. Define ProfileUpdateView.model, ProfileUpdateView.queryset, or override ProfileUpdateView.get_queryset().
Internal Server Error: /accounts/1/edit/
Traceback (most recent call last):
  File "/usr/local/lib/python3.10/site-packages/django/core/handlers/exception.py", line 55, in inner
    response = get_response(request)
  File "/usr/local/lib/python3.10/site-packages/django/core/handlers/base.py", line 197, in _get_response
    response = wrapped_callback(request, *callback_args, **callback_kwargs)
  File "/usr/local/lib/python3.10/site-packages/django/views/generic/base.py", line 84, in view
    return self.dispatch(request, *args, **kwargs)
  File "/usr/local/lib/python3.10/site-packages/django/contrib/auth/mixins.py", line 73, in dispatch
    return super().dispatch(request, *args, **kwargs)
  File "/usr/local/lib/python3.10/site-packages/django/contrib/auth/mixins.py", line 132, in dispatch
    user_test_result = self.get_test_func()()
  File "/code/accounts/views.py", line 20, in test_func
    user = self.get_object()
  File "/usr/local/lib/python3.10/site-packages/django/views/generic/detail.py", line 31, in get_object
    queryset = self.get_queryset()
  File "/usr/local/lib/python3.10/site-packages/django/views/generic/detail.py", line 72, in get_queryset
    raise ImproperlyConfigured(
django.core.exceptions.ImproperlyConfigured: ProfileUpdateView is missing a QuerySet. Define ProfileUpdateView.model, ProfileUpdateView.queryset, or override ProfileUpdateView.get_queryset().
Internal Server Error: /accounts/1/edit/
Traceback (most recent call last):
  File "/usr/local/lib/python3.10/site-packages/django/core/handlers/exception.py", line 55, in inner
    response = get_response(request)
  File "/usr/local/lib/python3.10/site-packages/django/core/handlers/base.py", line 197, in _get_response
    response = wrapped_callback(request, *callback_args, **callback_kwargs)
  File "/usr/local/lib/python3.10/site-packages/django/views/generic/base.py", line 84, in view
    return self.dispatch(request, *args, **kwargs)
  File "/usr/local/lib/python3.10/site-packages/django/contrib/auth/mixins.py", line 73, in dispatch
    return super().dispatch(request, *args, **kwargs)
  File "/usr/local/lib/python3.10/site-packages/django/contrib/auth/mixins.py", line 132, in dispatch
    user_test_result = self.get_test_func()()
  File "/code/accounts/views.py", line 20, in test_func
    user = self.get_object()
  File "/usr/local/lib/python3.10/site-packages/django/views/generic/detail.py", line 31, in get_object
    queryset = self.get_queryset()
  File "/usr/local/lib/python3.10/site-packages/django/views/generic/detail.py", line 72, in get_queryset
    raise ImproperlyConfigured(
django.core.exceptions.ImproperlyConfigured: ProfileUpdateView is missing a QuerySet. Define ProfileUpdateView.model, ProfileUpdateView.queryset, or override ProfileUpdateView.get_queryset().
Internal Server Error: /accounts/1/edit/
Traceback (most recent call last):
  File "/usr/local/lib/python3.10/site-packages/django/core/handlers/exception.py", line 55, in inner
    response = get_response(request)
  File "/usr/local/lib/python3.10/site-packages/django/core/handlers/base.py", line 197, in _get_response
    response = wrapped_callback(request, *callback_args, **callback_kwargs)
  File "/usr/local/lib/python3.10/site-packages/django/views/generic/base.py", line 84, in view
    return self.dispatch(request, *args, **kwargs)
  File "/usr/local/lib/python3.10/site-packages/django/contrib/auth/mixins.py", line 73, in dispatch
    return super().dispatch(request, *args, **kwargs)
  File "/usr/local/lib/python3.10/site-packages/django/contrib/auth/mixins.py", line 132, in dispatch
    user_test_result = self.get_test_func()()
  File "/code/accounts/views.py", line 20, in test_func
    user = self.get_object()
  File "/usr/local/lib/python3.10/site-packages/django/views/generic/detail.py", line 31, in get_object
    queryset = self.get_queryset()
  File "/usr/local/lib/python3.10/site-packages/django/views/generic/detail.py", line 72, in get_queryset
    raise ImproperlyConfigured(
django.core.exceptions.ImproperlyConfigured: ProfileUpdateView is missing a QuerySet. Define ProfileUpdateView.model, ProfileUpdateView.queryset, or override ProfileUpdateView.get_queryset().
Internal Server Error: /accounts/1/edit/
Traceback (most recent call last):
  File "/usr/local/lib/python3.10/site-packages/django/core/handlers/exception.py", line 55, in inner
    response = get_response(request)
  File "/usr/local/lib/python3.10/site-packages/django/core/handlers/base.py", line 197, in _get_response
    response = wrapped_callback(request, *callback_args, **callback_kwargs)
  File "/usr/local/lib/python3.10/site-packages/django/views/generic/base.py", line 84, in view
    return self.dispatch(request, *args, **kwargs)
  File "/usr/local/lib/python3.10/site-packages/django/contrib/auth/mixins.py", line 73, in dispatch
    return super().dispatch(request, *args, **kwargs)
  File "/usr/local/lib/python3.10/site-packages/django/contrib/auth/mixins.py", line 132, in dispatch
    user_test_result = self.get_test_func()()
  File "/code/accounts/views.py", line 20, in test_func
    user = self.get_object()
  File "/usr/local/lib/python3.10/site-packages/django/views/generic/detail.py", line 31, in get_object
    queryset = self.get_queryset()
  File "/usr/local/lib/python3.10/site-packages/django/views/generic/detail.py", line 72, in get_queryset
    raise ImproperlyConfigured(
django.core.exceptions.ImproperlyConfigured: ProfileUpdateView is missing a QuerySet. Define ProfileUpdateView.model, ProfileUpdateView.queryset, or override ProfileUpdateView.get_queryset().
Internal Server Error: /accounts/1/edit/
Traceback (most recent call last):
  File "/usr/local/lib/python3.10/site-packages/django/core/handlers/exception.py", line 55, in inner
    response = get_response(request)
  File "/usr/local/lib/python3.10/site-packages/django/core/handlers/base.py", line 197, in _get_response
    response = wrapped_callback(request, *callback_args, **callback_kwargs)
  File "/usr/local/lib/python3.10/site-packages/django/views/generic/base.py", line 84, in view
    return self.dispatch(request, *args, **kwargs)
  File "/usr/local/lib/python3.10/site-packages/django/contrib/auth/mixins.py", line 73, in dispatch
    return super().dispatch(request, *args, **kwargs)
  File "/usr/local/lib/python3.10/site-packages/django/contrib/auth/mixins.py", line 132, in dispatch
    user_test_result = self.get_test_func()()
  File "/code/accounts/views.py", line 20, in test_func
    user = self.get_object()
  File "/usr/local/lib/python3.10/site-packages/django/views/generic/detail.py", line 31, in get_object
    queryset = self.get_queryset()
  File "/usr/local/lib/python3.10/site-packages/django/views/generic/detail.py", line 72, in get_queryset
    raise ImproperlyConfigured(
django.core.exceptions.ImproperlyConfigured: ProfileUpdateView is missing a QuerySet. Define ProfileUpdateView.model, ProfileUpdateView.queryset, or override ProfileUpdateView.get_queryset().
Internal Server Error: /accounts/1/edit/
Traceback (most recent call last):
  File "/usr/local/lib/python3.10/site-packages/django/core/handlers/exception.py", line 55, in inner
    response = get_response(request)
  File "/usr/local/lib/python3.10/site-packages/django/core/handlers/base.py", line 197, in _get_response
    response = wrapped_callback(request, *callback_args, **callback_kwargs)
  File "/usr/local/lib/python3.10/site-packages/django/views/generic/base.py", line 84, in view
    return self.dispatch(request, *args, **kwargs)
  File "/usr/local/lib/python3.10/site-packages/django/contrib/auth/mixins.py", line 73, in dispatch
    return super().dispatch(request, *args, **kwargs)
  File "/usr/local/lib/python3.10/site-packages/django/contrib/auth/mixins.py", line 132, in dispatch
    user_test_result = self.get_test_func()()
  File "/code/accounts/views.py", line 20, in test_func
    user = self.get_object()
  File "/usr/local/lib/python3.10/site-packages/django/views/generic/detail.py", line 31, in get_object
    queryset = self.get_queryset()
  File "/usr/local/lib/python3.10/site-packages/django/views/generic/detail.py", line 72, in get_queryset
    raise ImproperlyConfigured(
django.core.exceptions.ImproperlyConfigured: ProfileUpdateView is missing a QuerySet. Define ProfileUpdateView.model, ProfileUpdateView.queryset, or override ProfileUpdateView.get_queryset().
Internal Server Error: /accounts/1/edit/
Traceback (most recent call last):
  File "/usr/local/lib/python3.10/site-packages/django/core/handlers/exception.py", line 55, in inner
    response = get_response(request)
  File "/usr/local/lib/python3.10/site-packages/django/core/handlers/base.py", line 197, in _get_response
    response = wrapped_callback(request, *callback_args, **callback_kwargs)
  File "/usr/local/lib/python3.10/site-packages/django/views/generic/base.py", line 84, in view
    return self.dispatch(request, *args, **kwargs)
  File "/usr/local/lib/python3.10/site-packages/django/contrib/auth/mixins.py", line 73, in dispatch
    return super().dispatch(request, *args, **kwargs)
  File "/usr/local/lib/python3.10/site-packages/django/contrib/auth/mixins.py", line 132, in dispatch
    user_test_result = self.get_test_func()()
  File "/code/accounts/views.py", line 20, in test_func
    user = self.get_object()
  File "/usr/local/lib/python3.10/site-packages/django/views/generic/detail.py", line 31, in get_object
    queryset = self.get_queryset()
  File "/usr/local/lib/python3.10/site-packages/django/views/generic/detail.py", line 72, in get_queryset
    raise ImproperlyConfigured(
django.core.exceptions.ImproperlyConfigured: ProfileUpdateView is missing a QuerySet. Define ProfileUpdateView.model, ProfileUpdateView.queryset, or override ProfileUpdateView.get_queryset().
Internal Server Error: /accounts/1/edit/
Traceback (most recent call last):
  File "/usr/local/lib/python3.10/site-packages/django/core/handlers/exception.py", line 55, in inner
    response = get_response(request)
  File "/usr/local/lib/python3.10/site-packages/django/core/handlers/base.py", line 197, in _get_response
    response = wrapped_callback(request, *callback_args, **callback_kwargs)
  File "/usr/local/lib/python3.10/site-packages/django/views/generic/base.py", line 84, in view
    return self.dispatch(request, *args, **kwargs)
  File "/usr/local/lib/python3.10/site-packages/django/contrib/auth/mixins.py", line 73, in dispatch
    return super().dispatch(request, *args, **kwargs)
  File "/usr/local/lib/python3.10/site-packages/django/contrib/auth/mixins.py", line 132, in dispatch
    user_test_result = self.get_test_func()()
  File "/code/accounts/views.py", line 20, in test_func
  File "/usr/local/lib/python3.10/site-packages/django/views/generic/detail.py", line 31, in get_object
    queryset = self.get_queryset()
  File "/usr/local/lib/python3.10/site-packages/django/views/generic/detail.py", line 72, in get_queryset
    raise ImproperlyConfigured(
django.core.exceptions.ImproperlyConfigured: ProfileUpdateView is missing a QuerySet. Define ProfileUpdateView.model, ProfileUpdateView.queryset, or override ProfileUpdateView.get_queryset().
Internal Server Error: /accounts/1/edit/
Traceback (most recent call last):
  File "/usr/local/lib/python3.10/site-packages/django/core/handlers/exception.py", line 55, in inner
    response = get_response(request)
  File "/usr/local/lib/python3.10/site-packages/django/core/handlers/base.py", line 197, in _get_response
    response = wrapped_callback(request, *callback_args, **callback_kwargs)
  File "/usr/local/lib/python3.10/site-packages/django/views/generic/base.py", line 84, in view
    return self.dispatch(request, *args, **kwargs)
  File "/usr/local/lib/python3.10/site-packages/django/contrib/auth/mixins.py", line 73, in dispatch
    return super().dispatch(request, *args, **kwargs)
  File "/usr/local/lib/python3.10/site-packages/django/contrib/auth/mixins.py", line 132, in dispatch
    user_test_result = self.get_test_func()()
  File "/code/accounts/views.py", line 20, in test_func
  File "/usr/local/lib/python3.10/site-packages/django/views/generic/detail.py", line 31, in get_object
    queryset = self.get_queryset()
  File "/usr/local/lib/python3.10/site-packages/django/views/generic/detail.py", line 72, in get_queryset
    raise ImproperlyConfigured(
django.core.exceptions.ImproperlyConfigured: ProfileUpdateView is missing a QuerySet. Define ProfileUpdateView.model, ProfileUpdateView.queryset, or override ProfileUpdateView.get_queryset().
Internal Server Error: /accounts/1/edit/
Traceback (most recent call last):
  File "/usr/local/lib/python3.10/site-packages/django/core/handlers/exception.py", line 55, in inner
    response = get_response(request)
  File "/usr/local/lib/python3.10/site-packages/django/core/handlers/base.py", line 197, in _get_response
    response = wrapped_callback(request, *callback_args, **callback_kwargs)
  File "/usr/local/lib/python3.10/site-packages/django/views/generic/base.py", line 84, in view
    return self.dispatch(request, *args, **kwargs)
  File "/usr/local/lib/python3.10/site-packages/django/contrib/auth/mixins.py", line 73, in dispatch
    return super().dispatch(request, *args, **kwargs)
  File "/usr/local/lib/python3.10/site-packages/django/contrib/auth/mixins.py", line 132, in dispatch
    user_test_result = self.get_test_func()()
  File "/code/accounts/views.py", line 20, in test_func
  File "/usr/local/lib/python3.10/site-packages/django/views/generic/detail.py", line 31, in get_object
    queryset = self.get_queryset()
  File "/usr/local/lib/python3.10/site-packages/django/views/generic/detail.py", line 72, in get_queryset
    raise ImproperlyConfigured(
django.core.exceptions.ImproperlyConfigured: ProfileUpdateView is missing a QuerySet. Define ProfileUpdateView.model, ProfileUpdateView.queryset, or override ProfileUpdateView.get_queryset().
Internal Server Error: /accounts/1/edit/
Traceback (most recent call last):
  File "/usr/local/lib/python3.10/site-packages/django/core/handlers/exception.py", line 55, in inner
    response = get_response(request)
  File "/usr/local/lib/python3.10/site-packages/django/core/handlers/base.py", line 197, in _get_response
    response = wrapped_callback(request, *callback_args, **callback_kwargs)
  File "/usr/local/lib/python3.10/site-packages/django/views/generic/base.py", line 84, in view
    return self.dispatch(request, *args, **kwargs)
  File "/usr/local/lib/python3.10/site-packages/django/contrib/auth/mixins.py", line 73, in dispatch
    return super().dispatch(request, *args, **kwargs)
  File "/usr/local/lib/python3.10/site-packages/django/views/generic/base.py", line 119, in dispatch
    return handler(request, *args, **kwargs)
  File "/usr/local/lib/python3.10/site-packages/django/views/generic/edit.py", line 203, in get
    self.object = self.get_object()
  File "/usr/local/lib/python3.10/site-packages/django/views/generic/detail.py", line 31, in get_object
    queryset = self.get_queryset()
  File "/usr/local/lib/python3.10/site-packages/django/views/generic/detail.py", line 72, in get_queryset
    raise ImproperlyConfigured(
django.core.exceptions.ImproperlyConfigured: ProfileUpdateView is missing a QuerySet. Define ProfileUpdateView.model, ProfileUpdateView.queryset, or override ProfileUpdateView.get_queryset().
Not Found: /static/images/favicon.png
Not Found: /favicon.ico/
Not Found: /static/debug_toolbar/css/print.css
Not Found: /static/debug_toolbar/js/utils.js
Not Found: /static/debug_toolbar/css/print.css
Not Found: /static/debug_toolbar/js/utils.js
Not Found: /static/debug_toolbar/css/print.css
Not Found: /static/debug_toolbar/js/utils.js
Not Found: /static/debug_toolbar/css/print.css
Not Found: /static/debug_toolbar/js/utils.js
Not Found: /static/debug_toolbar/css/print.css
Not Found: /static/debug_toolbar/js/utils.js
Not Found: /static/debug_toolbar/css/print.css
Not Found: /static/debug_toolbar/js/utils.js
Not Found: /static/debug_toolbar/css/print.css
Not Found: /static/debug_toolbar/js/utils.js
Not Found: /static/debug_toolbar/css/print.css
Not Found: /static/debug_toolbar/js/utils.js
Not Found: /static/debug_toolbar/css/print.css
Not Found: /static/debug_toolbar/js/utils.js
Not Found: /static/debug_toolbar/css/print.css
Not Found: /static/debug_toolbar/js/utils.js
Not Found: /static/debug_toolbar/css/print.css
Not Found: /static/debug_toolbar/js/utils.js
Not Found: /static/debug_toolbar/css/print.css
Not Found: /static/debug_toolbar/css/print.css
Not Found: /static/debug_toolbar/js/utils.js
Not Found: /static/debug_toolbar/css/print.css
Not Found: /static/debug_toolbar/js/utils.js
Not Found: /static/debug_toolbar/css/print.css
